2018-10-19 09:03:10,650 ERROR: Exception on / [GET] [in c:\users\q\appdata\local\programs\python\python36-32\lib\site-packages\flask\app.py:1761]
Traceback (most recent call last):
  File "c:\users\q\appdata\local\programs\python\python36-32\lib\site-packages\flask\app.py", line 2292, in wsgi_app
    response = self.full_dispatch_request()
  File "c:\users\q\appdata\local\programs\python\python36-32\lib\site-packages\flask\app.py", line 1815, in full_dispatch_request
    rv = self.handle_user_exception(e)
  File "c:\users\q\appdata\local\programs\python\python36-32\lib\site-packages\flask\app.py", line 1718, in handle_user_exception
    reraise(exc_type, exc_value, tb)
  File "c:\users\q\appdata\local\programs\python\python36-32\lib\site-packages\flask\_compat.py", line 35, in reraise
    raise value
  File "c:\users\q\appdata\local\programs\python\python36-32\lib\site-packages\flask\app.py", line 1811, in full_dispatch_request
    rv = self.preprocess_request()
  File "c:\users\q\appdata\local\programs\python\python36-32\lib\site-packages\flask\app.py", line 2087, in preprocess_request
    rv = func()
  File "D:\serialshow\app\routes.py", line 15, in before_request
    users.add(current_user.class_token)
AttributeError: 'tuple' object has no attribute 'add'
2018-10-19 09:03:10,788 ERROR: Exception on /static/css/404.css [GET] [in c:\users\q\appdata\local\programs\python\python36-32\lib\site-packages\flask\app.py:1761]
Traceback (most recent call last):
  File "c:\users\q\appdata\local\programs\python\python36-32\lib\site-packages\flask\app.py", line 2292, in wsgi_app
    response = self.full_dispatch_request()
  File "c:\users\q\appdata\local\programs\python\python36-32\lib\site-packages\flask\app.py", line 1815, in full_dispatch_request
    rv = self.handle_user_exception(e)
  File "c:\users\q\appdata\local\programs\python\python36-32\lib\site-packages\flask\app.py", line 1718, in handle_user_exception
    reraise(exc_type, exc_value, tb)
  File "c:\users\q\appdata\local\programs\python\python36-32\lib\site-packages\flask\_compat.py", line 35, in reraise
    raise value
  File "c:\users\q\appdata\local\programs\python\python36-32\lib\site-packages\flask\app.py", line 1811, in full_dispatch_request
    rv = self.preprocess_request()
  File "c:\users\q\appdata\local\programs\python\python36-32\lib\site-packages\flask\app.py", line 2087, in preprocess_request
    rv = func()
  File "D:\serialshow\app\routes.py", line 15, in before_request
    users.add(current_user.class_token)
AttributeError: 'tuple' object has no attribute 'add'
2018-10-19 09:03:10,805 ERROR: Exception on /static/css/404.css [GET] [in c:\users\q\appdata\local\programs\python\python36-32\lib\site-packages\flask\app.py:1761]
Traceback (most recent call last):
  File "c:\users\q\appdata\local\programs\python\python36-32\lib\site-packages\flask\app.py", line 2292, in wsgi_app
    response = self.full_dispatch_request()
  File "c:\users\q\appdata\local\programs\python\python36-32\lib\site-packages\flask\app.py", line 1815, in full_dispatch_request
    rv = self.handle_user_exception(e)
  File "c:\users\q\appdata\local\programs\python\python36-32\lib\site-packages\flask\app.py", line 1718, in handle_user_exception
    reraise(exc_type, exc_value, tb)
  File "c:\users\q\appdata\local\programs\python\python36-32\lib\site-packages\flask\_compat.py", line 35, in reraise
    raise value
  File "c:\users\q\appdata\local\programs\python\python36-32\lib\site-packages\flask\app.py", line 1811, in full_dispatch_request
    rv = self.preprocess_request()
  File "c:\users\q\appdata\local\programs\python\python36-32\lib\site-packages\flask\app.py", line 2087, in preprocess_request
    rv = func()
  File "D:\serialshow\app\routes.py", line 15, in before_request
    users.add(current_user.class_token)
AttributeError: 'tuple' object has no attribute 'add'
2018-10-19 09:10:10,227 INFO: Serialshow startup [in D:\serialshow\app\__init__.py:28]
2018-10-19 09:11:59,012 INFO: Serialshow startup [in D:\serialshow\app\__init__.py:28]
2018-10-19 09:32:00,121 INFO: Serialshow startup [in D:\serialshow\app\__init__.py:28]
2018-10-19 09:42:28,494 INFO: Serialshow startup [in D:\serialshow\app\__init__.py:28]
2018-10-19 09:58:58,526 INFO: Serialshow startup [in D:\serialshow\app\__init__.py:28]
2018-10-19 09:59:27,687 INFO: Serialshow startup [in D:\serialshow\app\__init__.py:28]
2018-10-19 09:59:40,719 INFO: Serialshow startup [in D:\serialshow\app\__init__.py:28]
2018-10-19 10:00:18,422 INFO: Serialshow startup [in D:\serialshow\app\__init__.py:28]
2018-10-19 10:01:07,174 INFO: Serialshow startup [in D:\serialshow\app\__init__.py:28]
2018-10-19 10:02:24,897 INFO: Serialshow startup [in D:\serialshow\app\__init__.py:28]
2018-10-19 10:04:06,400 INFO: Serialshow startup [in D:\serialshow\app\__init__.py:28]
2018-10-19 10:05:23,588 INFO: Serialshow startup [in D:\serialshow\app\__init__.py:28]
2018-10-19 10:09:22,446 INFO: Serialshow startup [in D:\serialshow\app\__init__.py:28]
2018-10-19 10:10:54,876 INFO: Serialshow startup [in D:\serialshow\app\__init__.py:28]
2018-10-19 10:12:09,941 INFO: Serialshow startup [in D:\serialshow\app\__init__.py:28]
2018-10-19 10:12:29,618 INFO: Serialshow startup [in D:\serialshow\app\__init__.py:28]
2018-10-19 10:13:28,345 INFO: Serialshow startup [in D:\serialshow\app\__init__.py:28]
2018-10-19 10:13:45,077 INFO: Serialshow startup [in D:\serialshow\app\__init__.py:28]
2018-10-19 10:14:40,325 INFO: Serialshow startup [in D:\serialshow\app\__init__.py:28]
2018-10-19 10:14:52,353 INFO: Serialshow startup [in D:\serialshow\app\__init__.py:28]
2018-10-19 10:15:41,838 INFO: Serialshow startup [in D:\serialshow\app\__init__.py:28]
2018-10-19 10:15:55,258 INFO: Serialshow startup [in D:\serialshow\app\__init__.py:28]
2018-10-19 10:16:02,444 INFO: Serialshow startup [in D:\serialshow\app\__init__.py:28]
2018-10-19 10:17:33,321 INFO: Serialshow startup [in D:\serialshow\app\__init__.py:28]
2018-10-19 10:17:50,212 INFO: Serialshow startup [in D:\serialshow\app\__init__.py:28]
2018-10-19 10:18:37,449 INFO: Serialshow startup [in D:\serialshow\app\__init__.py:28]
2018-10-19 10:19:22,315 INFO: Serialshow startup [in D:\serialshow\app\__init__.py:28]
2018-10-19 10:19:32,300 INFO: Serialshow startup [in D:\serialshow\app\__init__.py:28]
2018-10-19 10:19:40,420 INFO: Serialshow startup [in D:\serialshow\app\__init__.py:28]
