2018-10-22 15:45:31,862 INFO: Serialshow startup [in D:\serialshow\app\__init__.py:28]
2018-10-22 15:49:24,999 INFO: Serialshow startup [in D:\serialshow\app\__init__.py:28]
2018-10-22 15:52:25,026 INFO: Serialshow startup [in D:\serialshow\app\__init__.py:28]
2018-10-22 16:02:26,429 INFO: Serialshow startup [in D:\serialshow\app\__init__.py:28]
2018-10-22 16:03:25,336 INFO: Serialshow startup [in D:\serialshow\app\__init__.py:28]
2018-10-22 16:04:22,455 INFO: Serialshow startup [in D:\serialshow\app\__init__.py:28]
2018-10-22 16:05:50,529 INFO: Serialshow startup [in D:\serialshow\app\__init__.py:28]
2018-10-22 16:08:29,082 INFO: Serialshow startup [in D:\serialshow\app\__init__.py:28]
2018-10-22 16:08:32,711 ERROR: Exception on /index [GET] [in c:\users\q\appdata\local\programs\python\python36-32\lib\site-packages\flask\app.py:1761]
Traceback (most recent call last):
  File "c:\users\q\appdata\local\programs\python\python36-32\lib\site-packages\flask\app.py", line 2292, in wsgi_app
    response = self.full_dispatch_request()
  File "c:\users\q\appdata\local\programs\python\python36-32\lib\site-packages\flask\app.py", line 1815, in full_dispatch_request
    rv = self.handle_user_exception(e)
  File "c:\users\q\appdata\local\programs\python\python36-32\lib\site-packages\flask\app.py", line 1718, in handle_user_exception
    reraise(exc_type, exc_value, tb)
  File "c:\users\q\appdata\local\programs\python\python36-32\lib\site-packages\flask\_compat.py", line 35, in reraise
    raise value
  File "c:\users\q\appdata\local\programs\python\python36-32\lib\site-packages\flask\app.py", line 1813, in full_dispatch_request
    rv = self.dispatch_request()
  File "c:\users\q\appdata\local\programs\python\python36-32\lib\site-packages\flask\app.py", line 1799, in dispatch_request
    return self.view_functions[rule.endpoint](**req.view_args)
  File "c:\users\q\appdata\local\programs\python\python36-32\lib\site-packages\flask_login\utils.py", line 261, in decorated_view
    return func(*args, **kwargs)
  File "D:\serialshow\app\routes.py", line 30, in index
    r.hset("simultaneously")
TypeError: hset() missing 2 required positional arguments: 'key' and 'value'
2018-10-22 16:09:27,899 INFO: Serialshow startup [in D:\serialshow\app\__init__.py:28]
2018-10-22 16:09:30,105 ERROR: Exception on /index [GET] [in c:\users\q\appdata\local\programs\python\python36-32\lib\site-packages\flask\app.py:1761]
Traceback (most recent call last):
  File "c:\users\q\appdata\local\programs\python\python36-32\lib\site-packages\flask\app.py", line 2292, in wsgi_app
    response = self.full_dispatch_request()
  File "c:\users\q\appdata\local\programs\python\python36-32\lib\site-packages\flask\app.py", line 1815, in full_dispatch_request
    rv = self.handle_user_exception(e)
  File "c:\users\q\appdata\local\programs\python\python36-32\lib\site-packages\flask\app.py", line 1718, in handle_user_exception
    reraise(exc_type, exc_value, tb)
  File "c:\users\q\appdata\local\programs\python\python36-32\lib\site-packages\flask\_compat.py", line 35, in reraise
    raise value
  File "c:\users\q\appdata\local\programs\python\python36-32\lib\site-packages\flask\app.py", line 1813, in full_dispatch_request
    rv = self.dispatch_request()
  File "c:\users\q\appdata\local\programs\python\python36-32\lib\site-packages\flask\app.py", line 1799, in dispatch_request
    return self.view_functions[rule.endpoint](**req.view_args)
  File "c:\users\q\appdata\local\programs\python\python36-32\lib\site-packages\flask_login\utils.py", line 261, in decorated_view
    return func(*args, **kwargs)
  File "D:\serialshow\app\routes.py", line 29, in index
    r.hset("simultaneously", i)
TypeError: hset() missing 1 required positional argument: 'value'
2018-10-22 16:11:22,661 INFO: Serialshow startup [in D:\serialshow\app\__init__.py:28]
2018-10-22 16:14:30,562 INFO: Serialshow startup [in D:\serialshow\app\__init__.py:28]
2018-10-22 16:26:38,690 INFO: Serialshow startup [in D:\serialshow\app\__init__.py:28]
2018-10-22 16:27:17,345 INFO: Serialshow startup [in D:\serialshow\app\__init__.py:28]
2018-10-22 16:27:23,079 ERROR: Exception on /class/Êý¾Ý¿â [GET] [in c:\users\q\appdata\local\programs\python\python36-32\lib\site-packages\flask\app.py:1761]
Traceback (most recent call last):
  File "c:\users\q\appdata\local\programs\python\python36-32\lib\site-packages\flask\app.py", line 2292, in wsgi_app
    response = self.full_dispatch_request()
  File "c:\users\q\appdata\local\programs\python\python36-32\lib\site-packages\flask\app.py", line 1815, in full_dispatch_request
    rv = self.handle_user_exception(e)
  File "c:\users\q\appdata\local\programs\python\python36-32\lib\site-packages\flask\app.py", line 1718, in handle_user_exception
    reraise(exc_type, exc_value, tb)
  File "c:\users\q\appdata\local\programs\python\python36-32\lib\site-packages\flask\_compat.py", line 35, in reraise
    raise value
  File "c:\users\q\appdata\local\programs\python\python36-32\lib\site-packages\flask\app.py", line 1813, in full_dispatch_request
    rv = self.dispatch_request()
  File "c:\users\q\appdata\local\programs\python\python36-32\lib\site-packages\flask\app.py", line 1799, in dispatch_request
    return self.view_functions[rule.endpoint](**req.view_args)
  File "c:\users\q\appdata\local\programs\python\python36-32\lib\site-packages\flask_login\utils.py", line 261, in decorated_view
    return func(*args, **kwargs)
  File "D:\serialshow\app\routes.py", line 72, in get_class
    last_seen = curr_class.last_seen
AttributeError: 'NoneType' object has no attribute 'last_seen'
2018-10-22 16:28:14,755 INFO: Serialshow startup [in D:\serialshow\app\__init__.py:28]
2018-10-22 16:29:25,305 INFO: Serialshow startup [in D:\serialshow\app\__init__.py:28]
2018-10-22 16:30:06,572 INFO: Serialshow startup [in D:\serialshow\app\__init__.py:28]
2018-10-22 16:42:52,472 INFO: Serialshow startup [in D:\serialshow\app\__init__.py:28]
2018-10-22 16:44:49,922 INFO: Serialshow startup [in D:\serialshow\app\__init__.py:28]
2018-10-23 08:12:47,566 INFO: Serialshow startup [in D:\serialshow\app\__init__.py:28]
2018-10-23 08:14:34,010 INFO: Serialshow startup [in D:\serialshow\app\__init__.py:28]
