2018-11-02 10:26:36,318 ERROR: Exception on /api/class_history [GET] [in d:\serialshow\venv\lib\site-packages\flask\app.py:1761]
Traceback (most recent call last):
  File "d:\serialshow\venv\lib\site-packages\flask\app.py", line 2292, in wsgi_app
    response = self.full_dispatch_request()
  File "d:\serialshow\venv\lib\site-packages\flask\app.py", line 1815, in full_dispatch_request
    rv = self.handle_user_exception(e)
  File "d:\serialshow\venv\lib\site-packages\flask_cors\extension.py", line 161, in wrapped_function
    return cors_after_request(app.make_response(f(*args, **kwargs)))
  File "d:\serialshow\venv\lib\site-packages\flask\app.py", line 1718, in handle_user_exception
    reraise(exc_type, exc_value, tb)
  File "d:\serialshow\venv\lib\site-packages\flask\_compat.py", line 35, in reraise
    raise value
  File "d:\serialshow\venv\lib\site-packages\flask\app.py", line 1813, in full_dispatch_request
    rv = self.dispatch_request()
  File "d:\serialshow\venv\lib\site-packages\flask\app.py", line 1799, in dispatch_request
    return self.view_functions[rule.endpoint](**req.view_args)
  File "D:\serialshow\rfid-signin-python\app\routes.py", line 207, in class_history
    dict_format['time'] = log_info.time_time.strftime('%Y-%m-%d %H:%M:%S')
AttributeError: 'NoneType' object has no attribute 'time_time'
2018-11-02 10:26:37,335 ERROR: Exception on /api/class_history [GET] [in d:\serialshow\venv\lib\site-packages\flask\app.py:1761]
Traceback (most recent call last):
  File "d:\serialshow\venv\lib\site-packages\flask\app.py", line 2292, in wsgi_app
    response = self.full_dispatch_request()
  File "d:\serialshow\venv\lib\site-packages\flask\app.py", line 1815, in full_dispatch_request
    rv = self.handle_user_exception(e)
  File "d:\serialshow\venv\lib\site-packages\flask_cors\extension.py", line 161, in wrapped_function
    return cors_after_request(app.make_response(f(*args, **kwargs)))
  File "d:\serialshow\venv\lib\site-packages\flask\app.py", line 1718, in handle_user_exception
    reraise(exc_type, exc_value, tb)
  File "d:\serialshow\venv\lib\site-packages\flask\_compat.py", line 35, in reraise
    raise value
  File "d:\serialshow\venv\lib\site-packages\flask\app.py", line 1813, in full_dispatch_request
    rv = self.dispatch_request()
  File "d:\serialshow\venv\lib\site-packages\flask\app.py", line 1799, in dispatch_request
    return self.view_functions[rule.endpoint](**req.view_args)
  File "D:\serialshow\rfid-signin-python\app\routes.py", line 207, in class_history
    dict_format['time'] = log_info.time_time.strftime('%Y-%m-%d %H:%M:%S')
AttributeError: 'NoneType' object has no attribute 'time_time'
2018-11-02 10:27:16,425 ERROR: Exception on /api/class_history [GET] [in d:\serialshow\venv\lib\site-packages\flask\app.py:1761]
Traceback (most recent call last):
  File "d:\serialshow\venv\lib\site-packages\flask\app.py", line 2292, in wsgi_app
    response = self.full_dispatch_request()
  File "d:\serialshow\venv\lib\site-packages\flask\app.py", line 1815, in full_dispatch_request
    rv = self.handle_user_exception(e)
  File "d:\serialshow\venv\lib\site-packages\flask_cors\extension.py", line 161, in wrapped_function
    return cors_after_request(app.make_response(f(*args, **kwargs)))
  File "d:\serialshow\venv\lib\site-packages\flask\app.py", line 1718, in handle_user_exception
    reraise(exc_type, exc_value, tb)
  File "d:\serialshow\venv\lib\site-packages\flask\_compat.py", line 35, in reraise
    raise value
  File "d:\serialshow\venv\lib\site-packages\flask\app.py", line 1813, in full_dispatch_request
    rv = self.dispatch_request()
  File "d:\serialshow\venv\lib\site-packages\flask\app.py", line 1799, in dispatch_request
    return self.view_functions[rule.endpoint](**req.view_args)
  File "D:\serialshow\rfid-signin-python\app\routes.py", line 207, in class_history
    dict_format['time'] = log_info.time_time.strftime('%Y-%m-%d %H:%M:%S')
AttributeError: 'NoneType' object has no attribute 'time_time'
2018-11-02 10:27:17,280 ERROR: Exception on /api/class_history [GET] [in d:\serialshow\venv\lib\site-packages\flask\app.py:1761]
Traceback (most recent call last):
  File "d:\serialshow\venv\lib\site-packages\flask\app.py", line 2292, in wsgi_app
    response = self.full_dispatch_request()
  File "d:\serialshow\venv\lib\site-packages\flask\app.py", line 1815, in full_dispatch_request
    rv = self.handle_user_exception(e)
  File "d:\serialshow\venv\lib\site-packages\flask_cors\extension.py", line 161, in wrapped_function
    return cors_after_request(app.make_response(f(*args, **kwargs)))
  File "d:\serialshow\venv\lib\site-packages\flask\app.py", line 1718, in handle_user_exception
    reraise(exc_type, exc_value, tb)
  File "d:\serialshow\venv\lib\site-packages\flask\_compat.py", line 35, in reraise
    raise value
  File "d:\serialshow\venv\lib\site-packages\flask\app.py", line 1813, in full_dispatch_request
    rv = self.dispatch_request()
  File "d:\serialshow\venv\lib\site-packages\flask\app.py", line 1799, in dispatch_request
    return self.view_functions[rule.endpoint](**req.view_args)
  File "D:\serialshow\rfid-signin-python\app\routes.py", line 207, in class_history
    dict_format['time'] = log_info.time_time.strftime('%Y-%m-%d %H:%M:%S')
AttributeError: 'NoneType' object has no attribute 'time_time'
2018-11-02 10:27:17,403 ERROR: Exception on /api/class_history [GET] [in d:\serialshow\venv\lib\site-packages\flask\app.py:1761]
Traceback (most recent call last):
  File "d:\serialshow\venv\lib\site-packages\flask\app.py", line 2292, in wsgi_app
    response = self.full_dispatch_request()
  File "d:\serialshow\venv\lib\site-packages\flask\app.py", line 1815, in full_dispatch_request
    rv = self.handle_user_exception(e)
  File "d:\serialshow\venv\lib\site-packages\flask_cors\extension.py", line 161, in wrapped_function
    return cors_after_request(app.make_response(f(*args, **kwargs)))
  File "d:\serialshow\venv\lib\site-packages\flask\app.py", line 1718, in handle_user_exception
    reraise(exc_type, exc_value, tb)
  File "d:\serialshow\venv\lib\site-packages\flask\_compat.py", line 35, in reraise
    raise value
  File "d:\serialshow\venv\lib\site-packages\flask\app.py", line 1813, in full_dispatch_request
    rv = self.dispatch_request()
  File "d:\serialshow\venv\lib\site-packages\flask\app.py", line 1799, in dispatch_request
    return self.view_functions[rule.endpoint](**req.view_args)
  File "D:\serialshow\rfid-signin-python\app\routes.py", line 207, in class_history
    dict_format['time'] = log_info.time_time.strftime('%Y-%m-%d %H:%M:%S')
AttributeError: 'NoneType' object has no attribute 'time_time'
2018-11-02 10:27:17,528 ERROR: Exception on /api/class_history [GET] [in d:\serialshow\venv\lib\site-packages\flask\app.py:1761]
Traceback (most recent call last):
  File "d:\serialshow\venv\lib\site-packages\flask\app.py", line 2292, in wsgi_app
    response = self.full_dispatch_request()
  File "d:\serialshow\venv\lib\site-packages\flask\app.py", line 1815, in full_dispatch_request
    rv = self.handle_user_exception(e)
  File "d:\serialshow\venv\lib\site-packages\flask_cors\extension.py", line 161, in wrapped_function
    return cors_after_request(app.make_response(f(*args, **kwargs)))
  File "d:\serialshow\venv\lib\site-packages\flask\app.py", line 1718, in handle_user_exception
    reraise(exc_type, exc_value, tb)
  File "d:\serialshow\venv\lib\site-packages\flask\_compat.py", line 35, in reraise
    raise value
  File "d:\serialshow\venv\lib\site-packages\flask\app.py", line 1813, in full_dispatch_request
    rv = self.dispatch_request()
  File "d:\serialshow\venv\lib\site-packages\flask\app.py", line 1799, in dispatch_request
    return self.view_functions[rule.endpoint](**req.view_args)
  File "D:\serialshow\rfid-signin-python\app\routes.py", line 207, in class_history
    dict_format['time'] = log_info.time_time.strftime('%Y-%m-%d %H:%M:%S')
AttributeError: 'NoneType' object has no attribute 'time_time'
2018-11-02 10:27:38,104 ERROR: Exception on /api/class_history [GET] [in d:\serialshow\venv\lib\site-packages\flask\app.py:1761]
Traceback (most recent call last):
  File "d:\serialshow\venv\lib\site-packages\flask\app.py", line 2292, in wsgi_app
    response = self.full_dispatch_request()
  File "d:\serialshow\venv\lib\site-packages\flask\app.py", line 1815, in full_dispatch_request
    rv = self.handle_user_exception(e)
  File "d:\serialshow\venv\lib\site-packages\flask_cors\extension.py", line 161, in wrapped_function
    return cors_after_request(app.make_response(f(*args, **kwargs)))
  File "d:\serialshow\venv\lib\site-packages\flask\app.py", line 1718, in handle_user_exception
    reraise(exc_type, exc_value, tb)
  File "d:\serialshow\venv\lib\site-packages\flask\_compat.py", line 35, in reraise
    raise value
  File "d:\serialshow\venv\lib\site-packages\flask\app.py", line 1813, in full_dispatch_request
    rv = self.dispatch_request()
  File "d:\serialshow\venv\lib\site-packages\flask\app.py", line 1799, in dispatch_request
    return self.view_functions[rule.endpoint](**req.view_args)
  File "D:\serialshow\rfid-signin-python\app\routes.py", line 207, in class_history
    dict_format['time'] = log_info.time_time.strftime('%Y-%m-%d %H:%M:%S')
AttributeError: 'NoneType' object has no attribute 'time_time'
2018-11-02 10:29:30,928 INFO: Serialshow startup [in D:\serialshow\rfid-signin-python\app\__init__.py:30]
2018-11-02 10:32:38,340 INFO: Serialshow startup [in D:\serialshow\rfid-signin-python\app\__init__.py:30]
