2018-10-21 13:20:14,624 ERROR: Exception on / [GET] [in c:\users\q\appdata\local\programs\python\python36-32\lib\site-packages\flask\app.py:1761]
Traceback (most recent call last):
  File "c:\users\q\appdata\local\programs\python\python36-32\lib\site-packages\flask\app.py", line 2292, in wsgi_app
    response = self.full_dispatch_request()
  File "c:\users\q\appdata\local\programs\python\python36-32\lib\site-packages\flask\app.py", line 1815, in full_dispatch_request
    rv = self.handle_user_exception(e)
  File "c:\users\q\appdata\local\programs\python\python36-32\lib\site-packages\flask\app.py", line 1718, in handle_user_exception
    reraise(exc_type, exc_value, tb)
  File "c:\users\q\appdata\local\programs\python\python36-32\lib\site-packages\flask\_compat.py", line 35, in reraise
    raise value
  File "c:\users\q\appdata\local\programs\python\python36-32\lib\site-packages\flask\app.py", line 1813, in full_dispatch_request
    rv = self.dispatch_request()
  File "c:\users\q\appdata\local\programs\python\python36-32\lib\site-packages\flask\app.py", line 1799, in dispatch_request
    return self.view_functions[rule.endpoint](**req.view_args)
  File "D:\serialshow\app\routes.py", line 25, in index
    return render_template('index.html', currentTime=currentTime, curr_class=curr_class)
NameError: name 'curr_class' is not defined
2018-10-21 13:20:47,849 INFO: Serialshow startup [in D:\serialshow\app\__init__.py:28]
2018-10-21 13:28:13,357 INFO: Serialshow startup [in D:\serialshow\app\__init__.py:28]
2018-10-21 13:36:42,235 INFO: Serialshow startup [in D:\serialshow\app\__init__.py:28]
2018-10-21 13:36:51,019 ERROR: Exception on /index [GET] [in c:\users\q\appdata\local\programs\python\python36-32\lib\site-packages\flask\app.py:1761]
Traceback (most recent call last):
  File "c:\users\q\appdata\local\programs\python\python36-32\lib\site-packages\flask\app.py", line 2292, in wsgi_app
    response = self.full_dispatch_request()
  File "c:\users\q\appdata\local\programs\python\python36-32\lib\site-packages\flask\app.py", line 1815, in full_dispatch_request
    rv = self.handle_user_exception(e)
  File "c:\users\q\appdata\local\programs\python\python36-32\lib\site-packages\flask\app.py", line 1718, in handle_user_exception
    reraise(exc_type, exc_value, tb)
  File "c:\users\q\appdata\local\programs\python\python36-32\lib\site-packages\flask\_compat.py", line 35, in reraise
    raise value
  File "c:\users\q\appdata\local\programs\python\python36-32\lib\site-packages\flask\app.py", line 1813, in full_dispatch_request
    rv = self.dispatch_request()
  File "c:\users\q\appdata\local\programs\python\python36-32\lib\site-packages\flask\app.py", line 1799, in dispatch_request
    return self.view_functions[rule.endpoint](**req.view_args)
  File "D:\serialshow\app\routes.py", line 23, in index
    r.set('curr_token', current_user.class_token)
  File "c:\users\q\appdata\local\programs\python\python36-32\lib\site-packages\werkzeug\local.py", line 347, in __getattr__
    return getattr(self._get_current_object(), name)
AttributeError: 'AnonymousUserMixin' object has no attribute 'class_token'
2018-10-21 13:39:45,639 INFO: Serialshow startup [in D:\serialshow\app\__init__.py:28]
2018-10-21 13:39:50,472 ERROR: Exception on / [GET] [in c:\users\q\appdata\local\programs\python\python36-32\lib\site-packages\flask\app.py:1761]
Traceback (most recent call last):
  File "c:\users\q\appdata\local\programs\python\python36-32\lib\site-packages\flask\app.py", line 2292, in wsgi_app
    response = self.full_dispatch_request()
  File "c:\users\q\appdata\local\programs\python\python36-32\lib\site-packages\flask\app.py", line 1815, in full_dispatch_request
    rv = self.handle_user_exception(e)
  File "c:\users\q\appdata\local\programs\python\python36-32\lib\site-packages\flask\app.py", line 1718, in handle_user_exception
    reraise(exc_type, exc_value, tb)
  File "c:\users\q\appdata\local\programs\python\python36-32\lib\site-packages\flask\_compat.py", line 35, in reraise
    raise value
  File "c:\users\q\appdata\local\programs\python\python36-32\lib\site-packages\flask\app.py", line 1813, in full_dispatch_request
    rv = self.dispatch_request()
  File "c:\users\q\appdata\local\programs\python\python36-32\lib\site-packages\flask\app.py", line 1799, in dispatch_request
    return self.view_functions[rule.endpoint](**req.view_args)
  File "D:\serialshow\app\routes.py", line 23, in index
    r.set('curr_token', current_user.class_token)
  File "c:\users\q\appdata\local\programs\python\python36-32\lib\site-packages\werkzeug\local.py", line 347, in __getattr__
    return getattr(self._get_current_object(), name)
AttributeError: 'AnonymousUserMixin' object has no attribute 'class_token'
2018-10-21 13:41:43,454 INFO: Serialshow startup [in D:\serialshow\app\__init__.py:28]
2018-10-21 13:41:45,465 ERROR: Exception on / [GET] [in c:\users\q\appdata\local\programs\python\python36-32\lib\site-packages\flask\app.py:1761]
Traceback (most recent call last):
  File "c:\users\q\appdata\local\programs\python\python36-32\lib\site-packages\flask\app.py", line 2292, in wsgi_app
    response = self.full_dispatch_request()
  File "c:\users\q\appdata\local\programs\python\python36-32\lib\site-packages\flask\app.py", line 1815, in full_dispatch_request
    rv = self.handle_user_exception(e)
  File "c:\users\q\appdata\local\programs\python\python36-32\lib\site-packages\flask\app.py", line 1718, in handle_user_exception
    reraise(exc_type, exc_value, tb)
  File "c:\users\q\appdata\local\programs\python\python36-32\lib\site-packages\flask\_compat.py", line 35, in reraise
    raise value
  File "c:\users\q\appdata\local\programs\python\python36-32\lib\site-packages\flask\app.py", line 1813, in full_dispatch_request
    rv = self.dispatch_request()
  File "c:\users\q\appdata\local\programs\python\python36-32\lib\site-packages\flask\app.py", line 1799, in dispatch_request
    return self.view_functions[rule.endpoint](**req.view_args)
  File "D:\serialshow\app\routes.py", line 23, in index
    r.set('curr_token', current_user.class_token)
  File "c:\users\q\appdata\local\programs\python\python36-32\lib\site-packages\werkzeug\local.py", line 347, in __getattr__
    return getattr(self._get_current_object(), name)
AttributeError: 'AnonymousUserMixin' object has no attribute 'class_token'
2018-10-21 13:42:16,833 INFO: Serialshow startup [in D:\serialshow\app\__init__.py:28]
2018-10-21 13:43:19,948 INFO: Serialshow startup [in D:\serialshow\app\__init__.py:28]
2018-10-21 13:43:21,654 ERROR: Exception on /index [GET] [in c:\users\q\appdata\local\programs\python\python36-32\lib\site-packages\flask\app.py:1761]
Traceback (most recent call last):
  File "c:\users\q\appdata\local\programs\python\python36-32\lib\site-packages\flask\app.py", line 2292, in wsgi_app
    response = self.full_dispatch_request()
  File "c:\users\q\appdata\local\programs\python\python36-32\lib\site-packages\flask\app.py", line 1815, in full_dispatch_request
    rv = self.handle_user_exception(e)
  File "c:\users\q\appdata\local\programs\python\python36-32\lib\site-packages\flask\app.py", line 1718, in handle_user_exception
    reraise(exc_type, exc_value, tb)
  File "c:\users\q\appdata\local\programs\python\python36-32\lib\site-packages\flask\_compat.py", line 35, in reraise
    raise value
  File "c:\users\q\appdata\local\programs\python\python36-32\lib\site-packages\flask\app.py", line 1813, in full_dispatch_request
    rv = self.dispatch_request()
  File "c:\users\q\appdata\local\programs\python\python36-32\lib\site-packages\flask\app.py", line 1799, in dispatch_request
    return self.view_functions[rule.endpoint](**req.view_args)
  File "D:\serialshow\app\routes.py", line 23, in index
    r.set('curr_token', current_user.class_token)
  File "c:\users\q\appdata\local\programs\python\python36-32\lib\site-packages\werkzeug\local.py", line 347, in __getattr__
    return getattr(self._get_current_object(), name)
AttributeError: 'AnonymousUserMixin' object has no attribute 'class_token'
2018-10-21 13:43:36,864 INFO: Serialshow startup [in D:\serialshow\app\__init__.py:28]
2018-10-21 13:44:01,021 INFO: Serialshow startup [in D:\serialshow\app\__init__.py:28]
2018-10-21 13:45:07,984 INFO: Serialshow startup [in D:\serialshow\app\__init__.py:28]
2018-10-21 13:47:09,523 INFO: Serialshow startup [in D:\serialshow\app\__init__.py:28]
2018-10-21 13:47:37,570 INFO: Serialshow startup [in D:\serialshow\app\__init__.py:28]
2018-10-21 13:54:50,965 INFO: Serialshow startup [in D:\serialshow\app\__init__.py:28]
2018-10-21 18:40:51,935 INFO: Serialshow startup [in D:\serialshow\app\__init__.py:28]
2018-10-21 18:43:32,156 INFO: Serialshow startup [in D:\serialshow\app\__init__.py:28]
2018-10-21 18:44:52,183 INFO: Serialshow startup [in D:\serialshow\app\__init__.py:28]
2018-10-21 18:44:57,931 INFO: Serialshow startup [in D:\serialshow\app\__init__.py:28]
2018-10-21 18:46:41,290 INFO: Serialshow startup [in D:\serialshow\app\__init__.py:28]
2018-10-21 18:48:21,810 INFO: Serialshow startup [in D:\serialshow\app\__init__.py:28]
2018-10-21 18:49:43,355 INFO: Serialshow startup [in D:\serialshow\app\__init__.py:28]
2018-10-21 18:52:10,225 INFO: Serialshow startup [in D:\serialshow\app\__init__.py:28]
2018-10-21 18:53:58,113 INFO: Serialshow startup [in D:\serialshow\app\__init__.py:28]
2018-10-21 18:57:08,593 INFO: Serialshow startup [in D:\serialshow\app\__init__.py:28]
2018-10-21 18:57:38,288 INFO: Serialshow startup [in D:\serialshow\app\__init__.py:28]
2018-10-21 18:58:18,193 INFO: Serialshow startup [in D:\serialshow\app\__init__.py:28]
2018-10-21 22:10:06,478 INFO: Serialshow startup [in D:\serialshow\app\__init__.py:28]
2018-10-21 22:11:57,734 INFO: Serialshow startup [in D:\serialshow\app\__init__.py:28]
