2018-12-20 15:19:18,071 INFO: Serialshow startup [in D:\rfid\rfid-signin-python\app\__init__.py:36]
2018-12-20 15:19:19,587 ERROR: Exception on /group/TEST [GET] [in d:\rfid\venv\lib\site-packages\flask\app.py:1761]
Traceback (most recent call last):
  File "d:\rfid\venv\lib\site-packages\flask\app.py", line 2292, in wsgi_app
    response = self.full_dispatch_request()
  File "d:\rfid\venv\lib\site-packages\flask\app.py", line 1815, in full_dispatch_request
    rv = self.handle_user_exception(e)
  File "d:\rfid\venv\lib\site-packages\flask_cors\extension.py", line 161, in wrapped_function
    return cors_after_request(app.make_response(f(*args, **kwargs)))
  File "d:\rfid\venv\lib\site-packages\flask\app.py", line 1718, in handle_user_exception
    reraise(exc_type, exc_value, tb)
  File "d:\rfid\venv\lib\site-packages\flask\_compat.py", line 35, in reraise
    raise value
  File "d:\rfid\venv\lib\site-packages\flask\app.py", line 1813, in full_dispatch_request
    rv = self.dispatch_request()
  File "d:\rfid\venv\lib\site-packages\flask\app.py", line 1799, in dispatch_request
    return self.view_functions[rule.endpoint](**req.view_args)
  File "D:\rfid\rfid-signin-python\app\routes.py", line 240, in group
    result = kcluster(parent)
  File "D:\rfid\rfid-signin-python\app\algorithms\kmean.py", line 55, in kcluster
    for i in range(len(rows[0]))]
  File "D:\rfid\rfid-signin-python\app\algorithms\kmean.py", line 55, in <listcomp>
    for i in range(len(rows[0]))]
  File "D:\rfid\rfid-signin-python\app\algorithms\kmean.py", line 54, in <listcomp>
    ranges = [(min([row[i] for row in rows]), max([row[i] for row in rows]))
IndexError: list index out of range
2018-12-20 15:20:02,943 INFO: Serialshow startup [in D:\rfid\rfid-signin-python\app\__init__.py:36]
2018-12-20 15:20:05,147 ERROR: Exception on /group/TEST [GET] [in d:\rfid\venv\lib\site-packages\flask\app.py:1761]
Traceback (most recent call last):
  File "d:\rfid\venv\lib\site-packages\flask\app.py", line 2292, in wsgi_app
    response = self.full_dispatch_request()
  File "d:\rfid\venv\lib\site-packages\flask\app.py", line 1815, in full_dispatch_request
    rv = self.handle_user_exception(e)
  File "d:\rfid\venv\lib\site-packages\flask_cors\extension.py", line 161, in wrapped_function
    return cors_after_request(app.make_response(f(*args, **kwargs)))
  File "d:\rfid\venv\lib\site-packages\flask\app.py", line 1718, in handle_user_exception
    reraise(exc_type, exc_value, tb)
  File "d:\rfid\venv\lib\site-packages\flask\_compat.py", line 35, in reraise
    raise value
  File "d:\rfid\venv\lib\site-packages\flask\app.py", line 1813, in full_dispatch_request
    rv = self.dispatch_request()
  File "d:\rfid\venv\lib\site-packages\flask\app.py", line 1799, in dispatch_request
    return self.view_functions[rule.endpoint](**req.view_args)
  File "D:\rfid\rfid-signin-python\app\routes.py", line 240, in group
    result = kcluster(parent)
  File "D:\rfid\rfid-signin-python\app\algorithms\kmean.py", line 56, in kcluster
    for i in range(len(rows[0]))]
  File "D:\rfid\rfid-signin-python\app\algorithms\kmean.py", line 56, in <listcomp>
    for i in range(len(rows[0]))]
  File "D:\rfid\rfid-signin-python\app\algorithms\kmean.py", line 55, in <listcomp>
    ranges = [(min([row[i] for row in rows]), max([row[i] for row in rows]))
IndexError: list index out of range
2018-12-20 15:20:17,455 ERROR: Exception on /group/TEST [GET] [in d:\rfid\venv\lib\site-packages\flask\app.py:1761]
Traceback (most recent call last):
  File "d:\rfid\venv\lib\site-packages\flask\app.py", line 2292, in wsgi_app
    response = self.full_dispatch_request()
  File "d:\rfid\venv\lib\site-packages\flask\app.py", line 1815, in full_dispatch_request
    rv = self.handle_user_exception(e)
  File "d:\rfid\venv\lib\site-packages\flask_cors\extension.py", line 161, in wrapped_function
    return cors_after_request(app.make_response(f(*args, **kwargs)))
  File "d:\rfid\venv\lib\site-packages\flask\app.py", line 1718, in handle_user_exception
    reraise(exc_type, exc_value, tb)
  File "d:\rfid\venv\lib\site-packages\flask\_compat.py", line 35, in reraise
    raise value
  File "d:\rfid\venv\lib\site-packages\flask\app.py", line 1813, in full_dispatch_request
    rv = self.dispatch_request()
  File "d:\rfid\venv\lib\site-packages\flask\app.py", line 1799, in dispatch_request
    return self.view_functions[rule.endpoint](**req.view_args)
  File "D:\rfid\rfid-signin-python\app\routes.py", line 240, in group
    result = kcluster(parent)
  File "D:\rfid\rfid-signin-python\app\algorithms\kmean.py", line 56, in kcluster
    for i in range(len(rows[0]))]
  File "D:\rfid\rfid-signin-python\app\algorithms\kmean.py", line 56, in <listcomp>
    for i in range(len(rows[0]))]
  File "D:\rfid\rfid-signin-python\app\algorithms\kmean.py", line 55, in <listcomp>
    ranges = [(min([row[i] for row in rows]), max([row[i] for row in rows]))
IndexError: list index out of range
2018-12-20 15:21:17,221 INFO: Serialshow startup [in D:\rfid\rfid-signin-python\app\__init__.py:36]
2018-12-20 15:21:19,625 ERROR: Exception on /group/TEST [GET] [in d:\rfid\venv\lib\site-packages\flask\app.py:1761]
Traceback (most recent call last):
  File "d:\rfid\venv\lib\site-packages\flask\app.py", line 2292, in wsgi_app
    response = self.full_dispatch_request()
  File "d:\rfid\venv\lib\site-packages\flask\app.py", line 1815, in full_dispatch_request
    rv = self.handle_user_exception(e)
  File "d:\rfid\venv\lib\site-packages\flask_cors\extension.py", line 161, in wrapped_function
    return cors_after_request(app.make_response(f(*args, **kwargs)))
  File "d:\rfid\venv\lib\site-packages\flask\app.py", line 1718, in handle_user_exception
    reraise(exc_type, exc_value, tb)
  File "d:\rfid\venv\lib\site-packages\flask\_compat.py", line 35, in reraise
    raise value
  File "d:\rfid\venv\lib\site-packages\flask\app.py", line 1813, in full_dispatch_request
    rv = self.dispatch_request()
  File "d:\rfid\venv\lib\site-packages\flask\app.py", line 1799, in dispatch_request
    return self.view_functions[rule.endpoint](**req.view_args)
  File "D:\rfid\rfid-signin-python\app\routes.py", line 240, in group
    result = kcluster(parent)
  File "D:\rfid\rfid-signin-python\app\algorithms\kmean.py", line 56, in kcluster
    for i in range(len(rows[0]))]
  File "D:\rfid\rfid-signin-python\app\algorithms\kmean.py", line 56, in <listcomp>
    for i in range(len(rows[0]))]
  File "D:\rfid\rfid-signin-python\app\algorithms\kmean.py", line 55, in <listcomp>
    ranges = [(min([row[i] for row in rows]), max([row[i] for row in rows]))
IndexError: list index out of range
2018-12-20 15:22:11,047 INFO: Serialshow startup [in D:\rfid\rfid-signin-python\app\__init__.py:36]
2018-12-20 15:22:12,663 ERROR: Exception on /group/TEST [GET] [in d:\rfid\venv\lib\site-packages\flask\app.py:1761]
Traceback (most recent call last):
  File "d:\rfid\venv\lib\site-packages\flask\app.py", line 2292, in wsgi_app
    response = self.full_dispatch_request()
  File "d:\rfid\venv\lib\site-packages\flask\app.py", line 1815, in full_dispatch_request
    rv = self.handle_user_exception(e)
  File "d:\rfid\venv\lib\site-packages\flask_cors\extension.py", line 161, in wrapped_function
    return cors_after_request(app.make_response(f(*args, **kwargs)))
  File "d:\rfid\venv\lib\site-packages\flask\app.py", line 1718, in handle_user_exception
    reraise(exc_type, exc_value, tb)
  File "d:\rfid\venv\lib\site-packages\flask\_compat.py", line 35, in reraise
    raise value
  File "d:\rfid\venv\lib\site-packages\flask\app.py", line 1813, in full_dispatch_request
    rv = self.dispatch_request()
  File "d:\rfid\venv\lib\site-packages\flask\app.py", line 1799, in dispatch_request
    return self.view_functions[rule.endpoint](**req.view_args)
  File "D:\rfid\rfid-signin-python\app\routes.py", line 240, in group
    result = kcluster(parent)
  File "D:\rfid\rfid-signin-python\app\algorithms\kmean.py", line 69, in kcluster
    d = distance(clusters[i], row)
  File "D:\rfid\rfid-signin-python\app\algorithms\kmean.py", line 14, in person
    den = sqrt((sum1Sq-pow(sum1,2)/len(v1))*(sum2Sq-pow(sum2,2)/len(v1)))
ValueError: math domain error
2018-12-20 15:22:37,724 INFO: Serialshow startup [in D:\rfid\rfid-signin-python\app\__init__.py:36]
2018-12-20 15:22:39,774 ERROR: Exception on /group/TEST [GET] [in d:\rfid\venv\lib\site-packages\flask\app.py:1761]
Traceback (most recent call last):
  File "d:\rfid\venv\lib\site-packages\flask\app.py", line 2292, in wsgi_app
    response = self.full_dispatch_request()
  File "d:\rfid\venv\lib\site-packages\flask\app.py", line 1815, in full_dispatch_request
    rv = self.handle_user_exception(e)
  File "d:\rfid\venv\lib\site-packages\flask_cors\extension.py", line 161, in wrapped_function
    return cors_after_request(app.make_response(f(*args, **kwargs)))
  File "d:\rfid\venv\lib\site-packages\flask\app.py", line 1718, in handle_user_exception
    reraise(exc_type, exc_value, tb)
  File "d:\rfid\venv\lib\site-packages\flask\_compat.py", line 35, in reraise
    raise value
  File "d:\rfid\venv\lib\site-packages\flask\app.py", line 1813, in full_dispatch_request
    rv = self.dispatch_request()
  File "d:\rfid\venv\lib\site-packages\flask\app.py", line 1799, in dispatch_request
    return self.view_functions[rule.endpoint](**req.view_args)
  File "D:\rfid\rfid-signin-python\app\routes.py", line 240, in group
    result = kcluster(parent)
  File "D:\rfid\rfid-signin-python\app\algorithms\kmean.py", line 68, in kcluster
    d = distance(clusters[i], row)
  File "D:\rfid\rfid-signin-python\app\algorithms\kmean.py", line 14, in person
    den = sqrt((sum1Sq-pow(sum1,2)/len(v1))*(sum2Sq-pow(sum2,2)/len(v1)))
ValueError: math domain error
2018-12-20 15:23:18,331 INFO: Serialshow startup [in D:\rfid\rfid-signin-python\app\__init__.py:36]
2018-12-20 15:24:40,541 INFO: Serialshow startup [in D:\rfid\rfid-signin-python\app\__init__.py:36]
2018-12-20 15:25:18,122 INFO: Serialshow startup [in D:\rfid\rfid-signin-python\app\__init__.py:36]
