2018-11-06 09:04:43,895 ERROR: Exception on /signin [GET] [in d:\serialshow\venv\lib\site-packages\flask\app.py:1761]
Traceback (most recent call last):
  File "d:\serialshow\venv\lib\site-packages\flask\app.py", line 2292, in wsgi_app
    response = self.full_dispatch_request()
  File "d:\serialshow\venv\lib\site-packages\flask\app.py", line 1815, in full_dispatch_request
    rv = self.handle_user_exception(e)
  File "d:\serialshow\venv\lib\site-packages\flask_cors\extension.py", line 161, in wrapped_function
    return cors_after_request(app.make_response(f(*args, **kwargs)))
  File "d:\serialshow\venv\lib\site-packages\flask\app.py", line 1718, in handle_user_exception
    reraise(exc_type, exc_value, tb)
  File "d:\serialshow\venv\lib\site-packages\flask\_compat.py", line 35, in reraise
    raise value
  File "d:\serialshow\venv\lib\site-packages\flask\app.py", line 1813, in full_dispatch_request
    rv = self.dispatch_request()
  File "d:\serialshow\venv\lib\site-packages\flask\app.py", line 1799, in dispatch_request
    return self.view_functions[rule.endpoint](**req.view_args)
  File "D:\serialshow\rfid-signin-python\app\routes.py", line 152, in signin
    rfid_id = decode(secret, fake_id)
  File "D:\serialshow\rfid-signin-python\app\routes.py", line 32, in decode
    return "".join(dec).decode()
AttributeError: 'str' object has no attribute 'decode'
2018-11-06 09:14:12,214 INFO: Serialshow startup [in D:\serialshow\rfid-signin-python\app\__init__.py:36]
2018-11-06 09:14:31,737 ERROR: Exception on /signin [GET] [in d:\serialshow\venv\lib\site-packages\flask\app.py:1761]
Traceback (most recent call last):
  File "d:\serialshow\venv\lib\site-packages\flask\app.py", line 2292, in wsgi_app
    response = self.full_dispatch_request()
  File "d:\serialshow\venv\lib\site-packages\flask\app.py", line 1815, in full_dispatch_request
    rv = self.handle_user_exception(e)
  File "d:\serialshow\venv\lib\site-packages\flask_cors\extension.py", line 161, in wrapped_function
    return cors_after_request(app.make_response(f(*args, **kwargs)))
  File "d:\serialshow\venv\lib\site-packages\flask\app.py", line 1718, in handle_user_exception
    reraise(exc_type, exc_value, tb)
  File "d:\serialshow\venv\lib\site-packages\flask\_compat.py", line 35, in reraise
    raise value
  File "d:\serialshow\venv\lib\site-packages\flask\app.py", line 1813, in full_dispatch_request
    rv = self.dispatch_request()
  File "d:\serialshow\venv\lib\site-packages\flask\app.py", line 1799, in dispatch_request
    return self.view_functions[rule.endpoint](**req.view_args)
  File "D:\serialshow\rfid-signin-python\app\routes.py", line 152, in signin
    rfid_id = decode(secret, fake_id).decode('utf-8')
AttributeError: 'str' object has no attribute 'decode'
2018-11-06 09:16:12,108 ERROR: Exception on /signin [GET] [in d:\serialshow\venv\lib\site-packages\flask\app.py:1761]
Traceback (most recent call last):
  File "d:\serialshow\venv\lib\site-packages\flask\app.py", line 2292, in wsgi_app
    response = self.full_dispatch_request()
  File "d:\serialshow\venv\lib\site-packages\flask\app.py", line 1815, in full_dispatch_request
    rv = self.handle_user_exception(e)
  File "d:\serialshow\venv\lib\site-packages\flask_cors\extension.py", line 161, in wrapped_function
    return cors_after_request(app.make_response(f(*args, **kwargs)))
  File "d:\serialshow\venv\lib\site-packages\flask\app.py", line 1718, in handle_user_exception
    reraise(exc_type, exc_value, tb)
  File "d:\serialshow\venv\lib\site-packages\flask\_compat.py", line 35, in reraise
    raise value
  File "d:\serialshow\venv\lib\site-packages\flask\app.py", line 1813, in full_dispatch_request
    rv = self.dispatch_request()
  File "d:\serialshow\venv\lib\site-packages\flask\app.py", line 1799, in dispatch_request
    return self.view_functions[rule.endpoint](**req.view_args)
  File "D:\serialshow\rfid-signin-python\app\routes.py", line 152, in signin
    rfid_id = decode(secret, fake_id).decode('utf-8')
AttributeError: 'str' object has no attribute 'decode'
2018-11-06 09:19:10,052 INFO: Serialshow startup [in D:\serialshow\rfid-signin-python\app\__init__.py:36]
2018-11-06 09:19:38,920 INFO: Serialshow startup [in D:\serialshow\rfid-signin-python\app\__init__.py:36]
2018-11-06 09:19:42,411 ERROR: Exception on /signin [GET] [in d:\serialshow\venv\lib\site-packages\flask\app.py:1761]
Traceback (most recent call last):
  File "d:\serialshow\venv\lib\site-packages\flask\app.py", line 2292, in wsgi_app
    response = self.full_dispatch_request()
  File "d:\serialshow\venv\lib\site-packages\flask\app.py", line 1815, in full_dispatch_request
    rv = self.handle_user_exception(e)
  File "d:\serialshow\venv\lib\site-packages\flask_cors\extension.py", line 161, in wrapped_function
    return cors_after_request(app.make_response(f(*args, **kwargs)))
  File "d:\serialshow\venv\lib\site-packages\flask\app.py", line 1718, in handle_user_exception
    reraise(exc_type, exc_value, tb)
  File "d:\serialshow\venv\lib\site-packages\flask\_compat.py", line 35, in reraise
    raise value
  File "d:\serialshow\venv\lib\site-packages\flask\app.py", line 1813, in full_dispatch_request
    rv = self.dispatch_request()
  File "d:\serialshow\venv\lib\site-packages\flask\app.py", line 1799, in dispatch_request
    return self.view_functions[rule.endpoint](**req.view_args)
  File "D:\serialshow\rfid-signin-python\app\routes.py", line 157, in signin
    if student.rfid_id == rfid_id.decode():
AttributeError: 'str' object has no attribute 'decode'
2018-11-06 09:20:16,766 INFO: Serialshow startup [in D:\serialshow\rfid-signin-python\app\__init__.py:36]
2018-11-06 09:20:28,765 ERROR: Exception on /signin [GET] [in d:\serialshow\venv\lib\site-packages\flask\app.py:1761]
Traceback (most recent call last):
  File "d:\serialshow\venv\lib\site-packages\flask\app.py", line 2292, in wsgi_app
    response = self.full_dispatch_request()
  File "d:\serialshow\venv\lib\site-packages\flask\app.py", line 1815, in full_dispatch_request
    rv = self.handle_user_exception(e)
  File "d:\serialshow\venv\lib\site-packages\flask_cors\extension.py", line 161, in wrapped_function
    return cors_after_request(app.make_response(f(*args, **kwargs)))
  File "d:\serialshow\venv\lib\site-packages\flask\app.py", line 1718, in handle_user_exception
    reraise(exc_type, exc_value, tb)
  File "d:\serialshow\venv\lib\site-packages\flask\_compat.py", line 35, in reraise
    raise value
  File "d:\serialshow\venv\lib\site-packages\flask\app.py", line 1813, in full_dispatch_request
    rv = self.dispatch_request()
  File "d:\serialshow\venv\lib\site-packages\flask\app.py", line 1799, in dispatch_request
    return self.view_functions[rule.endpoint](**req.view_args)
  File "D:\serialshow\rfid-signin-python\app\routes.py", line 152, in signin
    rfid_id = str(decode(secret, fake_id), 'utf-8')
TypeError: decoding str is not supported
2018-11-06 09:21:45,500 INFO: Serialshow startup [in D:\serialshow\rfid-signin-python\app\__init__.py:36]
2018-11-06 09:23:42,150 INFO: Serialshow startup [in D:\serialshow\rfid-signin-python\app\__init__.py:36]
2018-11-06 09:24:07,502 INFO: Serialshow startup [in D:\serialshow\rfid-signin-python\app\__init__.py:36]
2018-11-06 09:25:19,244 INFO: Serialshow startup [in D:\serialshow\rfid-signin-python\app\__init__.py:36]
2018-11-06 09:25:42,836 INFO: Serialshow startup [in D:\serialshow\rfid-signin-python\app\__init__.py:36]
2018-11-06 09:26:06,290 INFO: Serialshow startup [in D:\serialshow\rfid-signin-python\app\__init__.py:36]
2018-11-06 09:27:07,089 INFO: Serialshow startup [in D:\serialshow\rfid-signin-python\app\__init__.py:36]
2018-11-06 09:27:09,807 ERROR: Exception on /signin [GET] [in d:\serialshow\venv\lib\site-packages\flask\app.py:1761]
Traceback (most recent call last):
  File "d:\serialshow\venv\lib\site-packages\flask\app.py", line 2292, in wsgi_app
    response = self.full_dispatch_request()
  File "d:\serialshow\venv\lib\site-packages\flask\app.py", line 1815, in full_dispatch_request
    rv = self.handle_user_exception(e)
  File "d:\serialshow\venv\lib\site-packages\flask_cors\extension.py", line 161, in wrapped_function
    return cors_after_request(app.make_response(f(*args, **kwargs)))
  File "d:\serialshow\venv\lib\site-packages\flask\app.py", line 1718, in handle_user_exception
    reraise(exc_type, exc_value, tb)
  File "d:\serialshow\venv\lib\site-packages\flask\_compat.py", line 35, in reraise
    raise value
  File "d:\serialshow\venv\lib\site-packages\flask\app.py", line 1813, in full_dispatch_request
    rv = self.dispatch_request()
  File "d:\serialshow\venv\lib\site-packages\flask\app.py", line 1799, in dispatch_request
    return self.view_functions[rule.endpoint](**req.view_args)
  File "D:\serialshow\rfid-signin-python\app\routes.py", line 152, in signin
    rfid_id = decode(secret, fake_id)[2][2]
IndexError: string index out of range
2018-11-06 09:34:29,020 INFO: Serialshow startup [in D:\serialshow\rfid-signin-python\app\__init__.py:36]
2018-11-06 09:34:48,784 INFO: Serialshow startup [in D:\serialshow\rfid-signin-python\app\__init__.py:36]
2018-11-06 09:35:12,763 INFO: Serialshow startup [in D:\serialshow\rfid-signin-python\app\__init__.py:36]
2018-11-06 09:35:32,648 INFO: Serialshow startup [in D:\serialshow\rfid-signin-python\app\__init__.py:36]
