2018-10-20 18:47:21,629 ERROR: Exception on /class/数据库 [GET] [in c:\users\q\appdata\local\programs\python\python36-32\lib\site-packages\flask\app.py:1761]
Traceback (most recent call last):
  File "c:\users\q\appdata\local\programs\python\python36-32\lib\site-packages\flask\app.py", line 2292, in wsgi_app
    response = self.full_dispatch_request()
  File "c:\users\q\appdata\local\programs\python\python36-32\lib\site-packages\flask\app.py", line 1815, in full_dispatch_request
    rv = self.handle_user_exception(e)
  File "c:\users\q\appdata\local\programs\python\python36-32\lib\site-packages\flask\app.py", line 1718, in handle_user_exception
    reraise(exc_type, exc_value, tb)
  File "c:\users\q\appdata\local\programs\python\python36-32\lib\site-packages\flask\_compat.py", line 35, in reraise
    raise value
  File "c:\users\q\appdata\local\programs\python\python36-32\lib\site-packages\flask\app.py", line 1813, in full_dispatch_request
    rv = self.dispatch_request()
  File "c:\users\q\appdata\local\programs\python\python36-32\lib\site-packages\flask\app.py", line 1799, in dispatch_request
    return self.view_functions[rule.endpoint](**req.view_args)
  File "c:\users\q\appdata\local\programs\python\python36-32\lib\site-packages\flask_login\utils.py", line 261, in decorated_view
    return func(*args, **kwargs)
  File "D:\serialshow\app\routes.py", line 70, in get_class
    time_time > datetime.now() - timedelta(hours=2)
NameError: name 'time_time' is not defined
2018-10-20 18:48:38,712 INFO: Serialshow startup [in D:\serialshow\app\__init__.py:28]
2018-10-20 18:51:28,935 ERROR: Exception on /signin [GET] [in c:\users\q\appdata\local\programs\python\python36-32\lib\site-packages\flask\app.py:1761]
Traceback (most recent call last):
  File "c:\users\q\appdata\local\programs\python\python36-32\lib\site-packages\flask\app.py", line 2292, in wsgi_app
    response = self.full_dispatch_request()
  File "c:\users\q\appdata\local\programs\python\python36-32\lib\site-packages\flask\app.py", line 1815, in full_dispatch_request
    rv = self.handle_user_exception(e)
  File "c:\users\q\appdata\local\programs\python\python36-32\lib\site-packages\flask\app.py", line 1718, in handle_user_exception
    reraise(exc_type, exc_value, tb)
  File "c:\users\q\appdata\local\programs\python\python36-32\lib\site-packages\flask\_compat.py", line 35, in reraise
    raise value
  File "c:\users\q\appdata\local\programs\python\python36-32\lib\site-packages\flask\app.py", line 1813, in full_dispatch_request
    rv = self.dispatch_request()
  File "c:\users\q\appdata\local\programs\python\python36-32\lib\site-packages\flask\app.py", line 1799, in dispatch_request
    return self.view_functions[rule.endpoint](**req.view_args)
  File "D:\serialshow\app\routes.py", line 100, in signin
    students = Class.get_student().all()
TypeError: get_student() missing 1 required positional argument: 'self'
2018-10-20 18:52:34,851 INFO: Serialshow startup [in D:\serialshow\app\__init__.py:28]
2018-10-20 18:52:37,213 ERROR: Exception on /signin [GET] [in c:\users\q\appdata\local\programs\python\python36-32\lib\site-packages\flask\app.py:1761]
Traceback (most recent call last):
  File "c:\users\q\appdata\local\programs\python\python36-32\lib\site-packages\flask\app.py", line 2292, in wsgi_app
    response = self.full_dispatch_request()
  File "c:\users\q\appdata\local\programs\python\python36-32\lib\site-packages\flask\app.py", line 1815, in full_dispatch_request
    rv = self.handle_user_exception(e)
  File "c:\users\q\appdata\local\programs\python\python36-32\lib\site-packages\flask\app.py", line 1718, in handle_user_exception
    reraise(exc_type, exc_value, tb)
  File "c:\users\q\appdata\local\programs\python\python36-32\lib\site-packages\flask\_compat.py", line 35, in reraise
    raise value
  File "c:\users\q\appdata\local\programs\python\python36-32\lib\site-packages\flask\app.py", line 1813, in full_dispatch_request
    rv = self.dispatch_request()
  File "c:\users\q\appdata\local\programs\python\python36-32\lib\site-packages\flask\app.py", line 1799, in dispatch_request
    return self.view_functions[rule.endpoint](**req.view_args)
  File "D:\serialshow\app\routes.py", line 102, in signin
    if student.rfid_id == rfid_id:
NameError: name 'student' is not defined
2018-10-20 18:52:53,946 INFO: Serialshow startup [in D:\serialshow\app\__init__.py:28]
2018-10-20 18:53:41,414 INFO: Serialshow startup [in D:\serialshow\app\__init__.py:28]
2018-10-20 18:54:37,334 INFO: Serialshow startup [in D:\serialshow\app\__init__.py:28]
2018-10-20 18:55:04,478 INFO: Serialshow startup [in D:\serialshow\app\__init__.py:28]
2018-10-20 18:55:39,165 INFO: Serialshow startup [in D:\serialshow\app\__init__.py:28]
2018-10-20 18:56:22,123 INFO: Serialshow startup [in D:\serialshow\app\__init__.py:28]
2018-10-20 18:57:44,584 ERROR: Exception on /signin [GET] [in c:\users\q\appdata\local\programs\python\python36-32\lib\site-packages\flask\app.py:1761]
Traceback (most recent call last):
  File "c:\users\q\appdata\local\programs\python\python36-32\lib\site-packages\flask\app.py", line 2292, in wsgi_app
    response = self.full_dispatch_request()
  File "c:\users\q\appdata\local\programs\python\python36-32\lib\site-packages\flask\app.py", line 1815, in full_dispatch_request
    rv = self.handle_user_exception(e)
  File "c:\users\q\appdata\local\programs\python\python36-32\lib\site-packages\flask\app.py", line 1718, in handle_user_exception
    reraise(exc_type, exc_value, tb)
  File "c:\users\q\appdata\local\programs\python\python36-32\lib\site-packages\flask\_compat.py", line 35, in reraise
    raise value
  File "c:\users\q\appdata\local\programs\python\python36-32\lib\site-packages\flask\app.py", line 1813, in full_dispatch_request
    rv = self.dispatch_request()
  File "c:\users\q\appdata\local\programs\python\python36-32\lib\site-packages\flask\app.py", line 1799, in dispatch_request
    return self.view_functions[rule.endpoint](**req.view_args)
  File "D:\serialshow\app\routes.py", line 99, in signin
    curr_class = Class.query.filter_by(class_token=current_user.class_token).first_or_404()
  File "c:\users\q\appdata\local\programs\python\python36-32\lib\site-packages\werkzeug\local.py", line 347, in __getattr__
    return getattr(self._get_current_object(), name)
AttributeError: 'AnonymousUserMixin' object has no attribute 'class_token'
2018-10-20 18:57:51,875 INFO: Serialshow startup [in D:\serialshow\app\__init__.py:28]
2018-10-20 18:58:47,977 INFO: Serialshow startup [in D:\serialshow\app\__init__.py:28]
2018-10-20 18:59:51,537 INFO: Serialshow startup [in D:\serialshow\app\__init__.py:28]
2018-10-20 19:00:05,523 INFO: Serialshow startup [in D:\serialshow\app\__init__.py:28]
2018-10-20 19:00:09,217 INFO: Serialshow startup [in D:\serialshow\app\__init__.py:28]
2018-10-20 19:01:00,064 INFO: Serialshow startup [in D:\serialshow\app\__init__.py:28]
2018-10-20 19:01:37,835 INFO: Serialshow startup [in D:\serialshow\app\__init__.py:28]
2018-10-20 19:02:42,011 INFO: Serialshow startup [in D:\serialshow\app\__init__.py:28]
2018-10-20 19:03:00,210 INFO: Serialshow startup [in D:\serialshow\app\__init__.py:28]
2018-10-20 19:04:22,180 INFO: Serialshow startup [in D:\serialshow\app\__init__.py:28]
2018-10-20 19:06:39,493 INFO: Serialshow startup [in D:\serialshow\app\__init__.py:28]
2018-10-20 19:06:41,779 ERROR: Exception on /class/RFID传感器 [GET] [in c:\users\q\appdata\local\programs\python\python36-32\lib\site-packages\flask\app.py:1761]
Traceback (most recent call last):
  File "c:\users\q\appdata\local\programs\python\python36-32\lib\site-packages\flask\app.py", line 2292, in wsgi_app
    response = self.full_dispatch_request()
  File "c:\users\q\appdata\local\programs\python\python36-32\lib\site-packages\flask\app.py", line 1815, in full_dispatch_request
    rv = self.handle_user_exception(e)
  File "c:\users\q\appdata\local\programs\python\python36-32\lib\site-packages\flask\app.py", line 1718, in handle_user_exception
    reraise(exc_type, exc_value, tb)
  File "c:\users\q\appdata\local\programs\python\python36-32\lib\site-packages\flask\_compat.py", line 35, in reraise
    raise value
  File "c:\users\q\appdata\local\programs\python\python36-32\lib\site-packages\flask\app.py", line 1813, in full_dispatch_request
    rv = self.dispatch_request()
  File "c:\users\q\appdata\local\programs\python\python36-32\lib\site-packages\flask\app.py", line 1799, in dispatch_request
    return self.view_functions[rule.endpoint](**req.view_args)
  File "c:\users\q\appdata\local\programs\python\python36-32\lib\site-packages\flask_login\utils.py", line 261, in decorated_view
    return func(*args, **kwargs)
  File "D:\serialshow\app\routes.py", line 73, in get_class
    print(curr_log_info.active)
AttributeError: 'NoneType' object has no attribute 'active'
2018-10-20 19:08:38,045 INFO: Serialshow startup [in D:\serialshow\app\__init__.py:28]
2018-10-20 19:09:08,970 INFO: Serialshow startup [in D:\serialshow\app\__init__.py:28]
2018-10-20 19:09:54,765 INFO: Serialshow startup [in D:\serialshow\app\__init__.py:28]
2018-10-20 19:10:32,087 INFO: Serialshow startup [in D:\serialshow\app\__init__.py:28]
2018-10-20 19:10:54,865 INFO: Serialshow startup [in D:\serialshow\app\__init__.py:28]
2018-10-20 19:20:57,950 INFO: Serialshow startup [in D:\serialshow\app\__init__.py:28]
2018-10-20 19:21:56,678 INFO: Serialshow startup [in D:\serialshow\app\__init__.py:28]
2018-10-20 19:22:35,911 INFO: Serialshow startup [in D:\serialshow\app\__init__.py:28]
2018-10-20 19:23:07,396 INFO: Serialshow startup [in D:\serialshow\app\__init__.py:28]
2018-10-20 19:23:23,299 INFO: Serialshow startup [in D:\serialshow\app\__init__.py:28]
2018-10-20 21:28:15,297 INFO: Serialshow startup [in D:\serialshow\app\__init__.py:28]
2018-10-20 21:30:20,195 INFO: Serialshow startup [in D:\serialshow\app\__init__.py:28]
2018-10-20 21:31:25,539 INFO: Serialshow startup [in D:\serialshow\app\__init__.py:28]
2018-10-20 21:36:52,614 INFO: Serialshow startup [in D:\serialshow\app\__init__.py:28]
