2018-11-04 15:24:39,406 INFO: Serialshow startup [in D:\serialshow\rfid-signin-python\app\__init__.py:30]
2018-11-04 15:24:41,360 ERROR: Exception on /group/TEST [GET] [in d:\serialshow\venv\lib\site-packages\flask\app.py:1761]
Traceback (most recent call last):
  File "d:\serialshow\venv\lib\site-packages\flask\app.py", line 2292, in wsgi_app
    response = self.full_dispatch_request()
  File "d:\serialshow\venv\lib\site-packages\flask\app.py", line 1815, in full_dispatch_request
    rv = self.handle_user_exception(e)
  File "d:\serialshow\venv\lib\site-packages\flask_cors\extension.py", line 161, in wrapped_function
    return cors_after_request(app.make_response(f(*args, **kwargs)))
  File "d:\serialshow\venv\lib\site-packages\flask\app.py", line 1718, in handle_user_exception
    reraise(exc_type, exc_value, tb)
  File "d:\serialshow\venv\lib\site-packages\flask\_compat.py", line 35, in reraise
    raise value
  File "d:\serialshow\venv\lib\site-packages\flask\app.py", line 1813, in full_dispatch_request
    rv = self.dispatch_request()
  File "d:\serialshow\venv\lib\site-packages\flask\app.py", line 1799, in dispatch_request
    return self.view_functions[rule.endpoint](**req.view_args)
  File "D:\serialshow\rfid-signin-python\app\routes.py", line 238, in group
    result[i][j] = dict[result[i][j]]
TypeError: list indices must be integers or slices, not list
2018-11-04 15:25:20,559 INFO: Serialshow startup [in D:\serialshow\rfid-signin-python\app\__init__.py:30]
2018-11-04 15:25:22,556 ERROR: Exception on /group/TEST [GET] [in d:\serialshow\venv\lib\site-packages\flask\app.py:1761]
Traceback (most recent call last):
  File "d:\serialshow\venv\lib\site-packages\flask\app.py", line 2292, in wsgi_app
    response = self.full_dispatch_request()
  File "d:\serialshow\venv\lib\site-packages\flask\app.py", line 1815, in full_dispatch_request
    rv = self.handle_user_exception(e)
  File "d:\serialshow\venv\lib\site-packages\flask_cors\extension.py", line 161, in wrapped_function
    return cors_after_request(app.make_response(f(*args, **kwargs)))
  File "d:\serialshow\venv\lib\site-packages\flask\app.py", line 1718, in handle_user_exception
    reraise(exc_type, exc_value, tb)
  File "d:\serialshow\venv\lib\site-packages\flask\_compat.py", line 35, in reraise
    raise value
  File "d:\serialshow\venv\lib\site-packages\flask\app.py", line 1813, in full_dispatch_request
    rv = self.dispatch_request()
  File "d:\serialshow\venv\lib\site-packages\flask\app.py", line 1799, in dispatch_request
    return self.view_functions[rule.endpoint](**req.view_args)
  File "D:\serialshow\rfid-signin-python\app\routes.py", line 238, in group
    result[i][j] = dict[result[i][j]]
IndexError: list index out of range
2018-11-04 15:25:48,950 INFO: Serialshow startup [in D:\serialshow\rfid-signin-python\app\__init__.py:30]
2018-11-04 15:28:09,679 INFO: Serialshow startup [in D:\serialshow\rfid-signin-python\app\__init__.py:30]
2018-11-04 15:28:11,365 ERROR: Exception on /group/TEST [GET] [in d:\serialshow\venv\lib\site-packages\flask\app.py:1761]
Traceback (most recent call last):
  File "d:\serialshow\venv\lib\site-packages\flask\app.py", line 2292, in wsgi_app
    response = self.full_dispatch_request()
  File "d:\serialshow\venv\lib\site-packages\flask\app.py", line 1815, in full_dispatch_request
    rv = self.handle_user_exception(e)
  File "d:\serialshow\venv\lib\site-packages\flask_cors\extension.py", line 161, in wrapped_function
    return cors_after_request(app.make_response(f(*args, **kwargs)))
  File "d:\serialshow\venv\lib\site-packages\flask\app.py", line 1718, in handle_user_exception
    reraise(exc_type, exc_value, tb)
  File "d:\serialshow\venv\lib\site-packages\flask\_compat.py", line 35, in reraise
    raise value
  File "d:\serialshow\venv\lib\site-packages\flask\app.py", line 1813, in full_dispatch_request
    rv = self.dispatch_request()
  File "d:\serialshow\venv\lib\site-packages\flask\app.py", line 1799, in dispatch_request
    return self.view_functions[rule.endpoint](**req.view_args)
  File "D:\serialshow\rfid-signin-python\app\routes.py", line 238, in group
    result[i][j] = names[result[i][j]]
IndexError: list index out of range
2018-11-04 15:33:56,599 INFO: Serialshow startup [in D:\serialshow\rfid-signin-python\app\__init__.py:30]
2018-11-04 15:34:00,301 ERROR: Exception on /group/TEST [GET] [in d:\serialshow\venv\lib\site-packages\flask\app.py:1761]
Traceback (most recent call last):
  File "d:\serialshow\venv\lib\site-packages\flask\app.py", line 2292, in wsgi_app
    response = self.full_dispatch_request()
  File "d:\serialshow\venv\lib\site-packages\flask\app.py", line 1815, in full_dispatch_request
    rv = self.handle_user_exception(e)
  File "d:\serialshow\venv\lib\site-packages\flask_cors\extension.py", line 161, in wrapped_function
    return cors_after_request(app.make_response(f(*args, **kwargs)))
  File "d:\serialshow\venv\lib\site-packages\flask\app.py", line 1718, in handle_user_exception
    reraise(exc_type, exc_value, tb)
  File "d:\serialshow\venv\lib\site-packages\flask\_compat.py", line 35, in reraise
    raise value
  File "d:\serialshow\venv\lib\site-packages\flask\app.py", line 1813, in full_dispatch_request
    rv = self.dispatch_request()
  File "d:\serialshow\venv\lib\site-packages\flask\app.py", line 1799, in dispatch_request
    return self.view_functions[rule.endpoint](**req.view_args)
  File "D:\serialshow\rfid-signin-python\app\routes.py", line 238, in group
    print(names[i][j])
IndexError: string index out of range
2018-11-04 15:34:34,650 INFO: Serialshow startup [in D:\serialshow\rfid-signin-python\app\__init__.py:30]
2018-11-04 15:34:36,634 ERROR: Exception on /group/TEST [GET] [in d:\serialshow\venv\lib\site-packages\flask\app.py:1761]
Traceback (most recent call last):
  File "d:\serialshow\venv\lib\site-packages\flask\app.py", line 2292, in wsgi_app
    response = self.full_dispatch_request()
  File "d:\serialshow\venv\lib\site-packages\flask\app.py", line 1815, in full_dispatch_request
    rv = self.handle_user_exception(e)
  File "d:\serialshow\venv\lib\site-packages\flask_cors\extension.py", line 161, in wrapped_function
    return cors_after_request(app.make_response(f(*args, **kwargs)))
  File "d:\serialshow\venv\lib\site-packages\flask\app.py", line 1718, in handle_user_exception
    reraise(exc_type, exc_value, tb)
  File "d:\serialshow\venv\lib\site-packages\flask\_compat.py", line 35, in reraise
    raise value
  File "d:\serialshow\venv\lib\site-packages\flask\app.py", line 1813, in full_dispatch_request
    rv = self.dispatch_request()
  File "d:\serialshow\venv\lib\site-packages\flask\app.py", line 1799, in dispatch_request
    return self.view_functions[rule.endpoint](**req.view_args)
  File "D:\serialshow\rfid-signin-python\app\routes.py", line 238, in group
    print(names[result[i][j]])
IndexError: list index out of range
2018-11-04 15:35:32,082 INFO: Serialshow startup [in D:\serialshow\rfid-signin-python\app\__init__.py:30]
2018-11-04 15:36:10,553 INFO: Serialshow startup [in D:\serialshow\rfid-signin-python\app\__init__.py:30]
2018-11-04 15:36:12,705 ERROR: Exception on /group/TEST [GET] [in d:\serialshow\venv\lib\site-packages\flask\app.py:1761]
Traceback (most recent call last):
  File "d:\serialshow\venv\lib\site-packages\flask\app.py", line 2292, in wsgi_app
    response = self.full_dispatch_request()
  File "d:\serialshow\venv\lib\site-packages\flask\app.py", line 1815, in full_dispatch_request
    rv = self.handle_user_exception(e)
  File "d:\serialshow\venv\lib\site-packages\flask_cors\extension.py", line 161, in wrapped_function
    return cors_after_request(app.make_response(f(*args, **kwargs)))
  File "d:\serialshow\venv\lib\site-packages\flask\app.py", line 1718, in handle_user_exception
    reraise(exc_type, exc_value, tb)
  File "d:\serialshow\venv\lib\site-packages\flask\_compat.py", line 35, in reraise
    raise value
  File "d:\serialshow\venv\lib\site-packages\flask\app.py", line 1813, in full_dispatch_request
    rv = self.dispatch_request()
  File "d:\serialshow\venv\lib\site-packages\flask\app.py", line 1799, in dispatch_request
    return self.view_functions[rule.endpoint](**req.view_args)
  File "D:\serialshow\rfid-signin-python\app\routes.py", line 239, in group
    print(result[i][j])
IndexError: list index out of range
2018-11-04 15:36:43,179 INFO: Serialshow startup [in D:\serialshow\rfid-signin-python\app\__init__.py:30]
2018-11-04 15:36:44,855 ERROR: Exception on /group/TEST [GET] [in d:\serialshow\venv\lib\site-packages\flask\app.py:1761]
Traceback (most recent call last):
  File "d:\serialshow\venv\lib\site-packages\flask\app.py", line 2292, in wsgi_app
    response = self.full_dispatch_request()
  File "d:\serialshow\venv\lib\site-packages\flask\app.py", line 1815, in full_dispatch_request
    rv = self.handle_user_exception(e)
  File "d:\serialshow\venv\lib\site-packages\flask_cors\extension.py", line 161, in wrapped_function
    return cors_after_request(app.make_response(f(*args, **kwargs)))
  File "d:\serialshow\venv\lib\site-packages\flask\app.py", line 1718, in handle_user_exception
    reraise(exc_type, exc_value, tb)
  File "d:\serialshow\venv\lib\site-packages\flask\_compat.py", line 35, in reraise
    raise value
  File "d:\serialshow\venv\lib\site-packages\flask\app.py", line 1813, in full_dispatch_request
    rv = self.dispatch_request()
  File "d:\serialshow\venv\lib\site-packages\flask\app.py", line 1799, in dispatch_request
    return self.view_functions[rule.endpoint](**req.view_args)
  File "D:\serialshow\rfid-signin-python\app\routes.py", line 238, in group
    print(result[i][j])
IndexError: list index out of range
2018-11-04 15:37:20,177 INFO: Serialshow startup [in D:\serialshow\rfid-signin-python\app\__init__.py:30]
2018-11-04 15:38:58,022 INFO: Serialshow startup [in D:\serialshow\rfid-signin-python\app\__init__.py:30]
