2018-11-02 12:36:21,339 ERROR: Exception on /api/class_history [GET] [in d:\serialshow\venv\lib\site-packages\flask\app.py:1761]
Traceback (most recent call last):
  File "d:\serialshow\venv\lib\site-packages\flask\app.py", line 2292, in wsgi_app
    response = self.full_dispatch_request()
  File "d:\serialshow\venv\lib\site-packages\flask\app.py", line 1815, in full_dispatch_request
    rv = self.handle_user_exception(e)
  File "d:\serialshow\venv\lib\site-packages\flask_cors\extension.py", line 161, in wrapped_function
    return cors_after_request(app.make_response(f(*args, **kwargs)))
  File "d:\serialshow\venv\lib\site-packages\flask\app.py", line 1718, in handle_user_exception
    reraise(exc_type, exc_value, tb)
  File "d:\serialshow\venv\lib\site-packages\flask\_compat.py", line 35, in reraise
    raise value
  File "d:\serialshow\venv\lib\site-packages\flask\app.py", line 1813, in full_dispatch_request
    rv = self.dispatch_request()
  File "d:\serialshow\venv\lib\site-packages\flask\app.py", line 1799, in dispatch_request
    return self.view_functions[rule.endpoint](**req.view_args)
  File "D:\serialshow\rfid-signin-python\app\routes.py", line 211, in class_history
    dict_format['time'] = log_info.time_time.strftime('%Y-%m-%d %H:%M:%S')
AttributeError: 'NoneType' object has no attribute 'time_time'
2018-11-02 12:37:05,366 INFO: Serialshow startup [in D:\serialshow\rfid-signin-python\app\__init__.py:30]
2018-11-02 12:38:48,335 INFO: Serialshow startup [in D:\serialshow\rfid-signin-python\app\__init__.py:30]
2018-11-02 12:39:01,504 ERROR: Exception on /api/class_history [GET] [in d:\serialshow\venv\lib\site-packages\flask\app.py:1761]
Traceback (most recent call last):
  File "d:\serialshow\venv\lib\site-packages\flask\app.py", line 2292, in wsgi_app
    response = self.full_dispatch_request()
  File "d:\serialshow\venv\lib\site-packages\flask\app.py", line 1815, in full_dispatch_request
    rv = self.handle_user_exception(e)
  File "d:\serialshow\venv\lib\site-packages\flask_cors\extension.py", line 161, in wrapped_function
    return cors_after_request(app.make_response(f(*args, **kwargs)))
  File "d:\serialshow\venv\lib\site-packages\flask\app.py", line 1718, in handle_user_exception
    reraise(exc_type, exc_value, tb)
  File "d:\serialshow\venv\lib\site-packages\flask\_compat.py", line 35, in reraise
    raise value
  File "d:\serialshow\venv\lib\site-packages\flask\app.py", line 1813, in full_dispatch_request
    rv = self.dispatch_request()
  File "d:\serialshow\venv\lib\site-packages\flask\app.py", line 1799, in dispatch_request
    return self.view_functions[rule.endpoint](**req.view_args)
  File "D:\serialshow\rfid-signin-python\app\routes.py", line 211, in class_history
    dict_format['time'] = log_info.time_time.strftime('%Y-%m-%d %H:%M:%S')
AttributeError: 'BaseQuery' object has no attribute 'time_time'
2018-11-02 13:59:06,956 INFO: Serialshow startup [in D:\serialshow\rfid-signin-python\app\__init__.py:30]
2018-11-02 13:59:11,454 ERROR: Exception on /api/class_history [GET] [in d:\serialshow\venv\lib\site-packages\flask\app.py:1761]
Traceback (most recent call last):
  File "d:\serialshow\venv\lib\site-packages\flask\app.py", line 2292, in wsgi_app
    response = self.full_dispatch_request()
  File "d:\serialshow\venv\lib\site-packages\flask\app.py", line 1815, in full_dispatch_request
    rv = self.handle_user_exception(e)
  File "d:\serialshow\venv\lib\site-packages\flask_cors\extension.py", line 161, in wrapped_function
    return cors_after_request(app.make_response(f(*args, **kwargs)))
  File "d:\serialshow\venv\lib\site-packages\flask\app.py", line 1718, in handle_user_exception
    reraise(exc_type, exc_value, tb)
  File "d:\serialshow\venv\lib\site-packages\flask\_compat.py", line 35, in reraise
    raise value
  File "d:\serialshow\venv\lib\site-packages\flask\app.py", line 1813, in full_dispatch_request
    rv = self.dispatch_request()
  File "d:\serialshow\venv\lib\site-packages\flask\app.py", line 1799, in dispatch_request
    return self.view_functions[rule.endpoint](**req.view_args)
  File "D:\serialshow\rfid-signin-python\app\routes.py", line 197, in class_history
    primt(time_format)
NameError: name 'primt' is not defined
2018-11-02 13:59:27,201 INFO: Serialshow startup [in D:\serialshow\rfid-signin-python\app\__init__.py:30]
2018-11-02 13:59:31,157 ERROR: Exception on /api/class_history [GET] [in d:\serialshow\venv\lib\site-packages\flask\app.py:1761]
Traceback (most recent call last):
  File "d:\serialshow\venv\lib\site-packages\flask\app.py", line 2292, in wsgi_app
    response = self.full_dispatch_request()
  File "d:\serialshow\venv\lib\site-packages\flask\app.py", line 1815, in full_dispatch_request
    rv = self.handle_user_exception(e)
  File "d:\serialshow\venv\lib\site-packages\flask_cors\extension.py", line 161, in wrapped_function
    return cors_after_request(app.make_response(f(*args, **kwargs)))
  File "d:\serialshow\venv\lib\site-packages\flask\app.py", line 1718, in handle_user_exception
    reraise(exc_type, exc_value, tb)
  File "d:\serialshow\venv\lib\site-packages\flask\_compat.py", line 35, in reraise
    raise value
  File "d:\serialshow\venv\lib\site-packages\flask\app.py", line 1813, in full_dispatch_request
    rv = self.dispatch_request()
  File "d:\serialshow\venv\lib\site-packages\flask\app.py", line 1799, in dispatch_request
    return self.view_functions[rule.endpoint](**req.view_args)
  File "D:\serialshow\rfid-signin-python\app\routes.py", line 212, in class_history
    dict_format['time'] = log_info.time_time.strftime('%Y-%m-%d %H:%M:%S')
AttributeError: 'BaseQuery' object has no attribute 'time_time'
2018-11-02 14:00:54,863 INFO: Serialshow startup [in D:\serialshow\rfid-signin-python\app\__init__.py:30]
2018-11-02 14:00:58,025 ERROR: Exception on /api/class_history [GET] [in d:\serialshow\venv\lib\site-packages\flask\app.py:1761]
Traceback (most recent call last):
  File "d:\serialshow\venv\lib\site-packages\flask\app.py", line 2292, in wsgi_app
    response = self.full_dispatch_request()
  File "d:\serialshow\venv\lib\site-packages\flask\app.py", line 1815, in full_dispatch_request
    rv = self.handle_user_exception(e)
  File "d:\serialshow\venv\lib\site-packages\flask_cors\extension.py", line 161, in wrapped_function
    return cors_after_request(app.make_response(f(*args, **kwargs)))
  File "d:\serialshow\venv\lib\site-packages\flask\app.py", line 1718, in handle_user_exception
    reraise(exc_type, exc_value, tb)
  File "d:\serialshow\venv\lib\site-packages\flask\_compat.py", line 35, in reraise
    raise value
  File "d:\serialshow\venv\lib\site-packages\flask\app.py", line 1813, in full_dispatch_request
    rv = self.dispatch_request()
  File "d:\serialshow\venv\lib\site-packages\flask\app.py", line 1799, in dispatch_request
    return self.view_functions[rule.endpoint](**req.view_args)
  File "D:\serialshow\rfid-signin-python\app\routes.py", line 197, in class_history
    print('time_format is ' + time_format)
TypeError: must be str, not datetime.datetime
2018-11-02 14:01:43,461 INFO: Serialshow startup [in D:\serialshow\rfid-signin-python\app\__init__.py:30]
2018-11-02 14:01:46,466 ERROR: Exception on /api/class_history [GET] [in d:\serialshow\venv\lib\site-packages\flask\app.py:1761]
Traceback (most recent call last):
  File "d:\serialshow\venv\lib\site-packages\flask\app.py", line 2292, in wsgi_app
    response = self.full_dispatch_request()
  File "d:\serialshow\venv\lib\site-packages\flask\app.py", line 1815, in full_dispatch_request
    rv = self.handle_user_exception(e)
  File "d:\serialshow\venv\lib\site-packages\flask_cors\extension.py", line 161, in wrapped_function
    return cors_after_request(app.make_response(f(*args, **kwargs)))
  File "d:\serialshow\venv\lib\site-packages\flask\app.py", line 1718, in handle_user_exception
    reraise(exc_type, exc_value, tb)
  File "d:\serialshow\venv\lib\site-packages\flask\_compat.py", line 35, in reraise
    raise value
  File "d:\serialshow\venv\lib\site-packages\flask\app.py", line 1813, in full_dispatch_request
    rv = self.dispatch_request()
  File "d:\serialshow\venv\lib\site-packages\flask\app.py", line 1799, in dispatch_request
    return self.view_functions[rule.endpoint](**req.view_args)
  File "D:\serialshow\rfid-signin-python\app\routes.py", line 212, in class_history
    dict_format['time'] = log_info.time_time.strftime('%Y-%m-%d %H:%M:%S')
AttributeError: 'NoneType' object has no attribute 'time_time'
2018-11-02 14:02:41,945 INFO: Serialshow startup [in D:\serialshow\rfid-signin-python\app\__init__.py:30]
2018-11-02 14:02:44,000 ERROR: Exception on /api/class_history [GET] [in d:\serialshow\venv\lib\site-packages\flask\app.py:1761]
Traceback (most recent call last):
  File "d:\serialshow\venv\lib\site-packages\flask\app.py", line 2292, in wsgi_app
    response = self.full_dispatch_request()
  File "d:\serialshow\venv\lib\site-packages\flask\app.py", line 1815, in full_dispatch_request
    rv = self.handle_user_exception(e)
  File "d:\serialshow\venv\lib\site-packages\flask_cors\extension.py", line 161, in wrapped_function
    return cors_after_request(app.make_response(f(*args, **kwargs)))
  File "d:\serialshow\venv\lib\site-packages\flask\app.py", line 1718, in handle_user_exception
    reraise(exc_type, exc_value, tb)
  File "d:\serialshow\venv\lib\site-packages\flask\_compat.py", line 35, in reraise
    raise value
  File "d:\serialshow\venv\lib\site-packages\flask\app.py", line 1813, in full_dispatch_request
    rv = self.dispatch_request()
  File "d:\serialshow\venv\lib\site-packages\flask\app.py", line 1799, in dispatch_request
    return self.view_functions[rule.endpoint](**req.view_args)
  File "D:\serialshow\rfid-signin-python\app\routes.py", line 210, in class_history
    print(log_info.time_time)
AttributeError: 'NoneType' object has no attribute 'time_time'
2018-11-02 14:03:27,806 INFO: Serialshow startup [in D:\serialshow\rfid-signin-python\app\__init__.py:30]
