2018-12-19 14:50:10,401 ERROR: Exception on /group/TEST [GET] [in d:\rfid\venv\lib\site-packages\flask\app.py:1761]
Traceback (most recent call last):
  File "d:\rfid\venv\lib\site-packages\flask\app.py", line 2292, in wsgi_app
    response = self.full_dispatch_request()
  File "d:\rfid\venv\lib\site-packages\flask\app.py", line 1815, in full_dispatch_request
    rv = self.handle_user_exception(e)
  File "d:\rfid\venv\lib\site-packages\flask_cors\extension.py", line 161, in wrapped_function
    return cors_after_request(app.make_response(f(*args, **kwargs)))
  File "d:\rfid\venv\lib\site-packages\flask\app.py", line 1718, in handle_user_exception
    reraise(exc_type, exc_value, tb)
  File "d:\rfid\venv\lib\site-packages\flask\_compat.py", line 35, in reraise
    raise value
  File "d:\rfid\venv\lib\site-packages\flask\app.py", line 1813, in full_dispatch_request
    rv = self.dispatch_request()
  File "d:\rfid\venv\lib\site-packages\flask\app.py", line 1799, in dispatch_request
    return self.view_functions[rule.endpoint](**req.view_args)
  File "D:\rfid\rfid-signin-python\app\routes.py", line 240, in group
    result = kcluster(parent)
  File "D:\rfid\rfid-signin-python\app\algorithms\kmean.py", line 25, in kcluster
    for i in range(len(rows[0]))]
  File "D:\rfid\rfid-signin-python\app\algorithms\kmean.py", line 25, in <listcomp>
    for i in range(len(rows[0]))]
  File "D:\rfid\rfid-signin-python\app\algorithms\kmean.py", line 24, in <listcomp>
    ranges = [(min([row[i] for row in rows]), max([row[i] for row in rows]))
IndexError: list index out of range
2018-12-19 14:50:45,272 ERROR: Exception on /group/TEST [GET] [in d:\rfid\venv\lib\site-packages\flask\app.py:1761]
Traceback (most recent call last):
  File "d:\rfid\venv\lib\site-packages\flask\app.py", line 2292, in wsgi_app
    response = self.full_dispatch_request()
  File "d:\rfid\venv\lib\site-packages\flask\app.py", line 1815, in full_dispatch_request
    rv = self.handle_user_exception(e)
  File "d:\rfid\venv\lib\site-packages\flask_cors\extension.py", line 161, in wrapped_function
    return cors_after_request(app.make_response(f(*args, **kwargs)))
  File "d:\rfid\venv\lib\site-packages\flask\app.py", line 1718, in handle_user_exception
    reraise(exc_type, exc_value, tb)
  File "d:\rfid\venv\lib\site-packages\flask\_compat.py", line 35, in reraise
    raise value
  File "d:\rfid\venv\lib\site-packages\flask\app.py", line 1813, in full_dispatch_request
    rv = self.dispatch_request()
  File "d:\rfid\venv\lib\site-packages\flask\app.py", line 1799, in dispatch_request
    return self.view_functions[rule.endpoint](**req.view_args)
  File "D:\rfid\rfid-signin-python\app\routes.py", line 240, in group
    result = kcluster(parent)
  File "D:\rfid\rfid-signin-python\app\algorithms\kmean.py", line 25, in kcluster
    clusters = [[random.random()*(ranges[i][1]-ranges[i][0])+ranges[i][0]
  File "D:\rfid\rfid-signin-python\app\algorithms\kmean.py", line 25, in <listcomp>
    clusters = [[random.random()*(ranges[i][1]-ranges[i][0])+ranges[i][0]
  File "D:\rfid\rfid-signin-python\app\algorithms\kmean.py", line 24, in <listcomp>
    for i in range(len(rows[0]))]
IndexError: list index out of range
2018-12-19 14:51:00,169 INFO: Serialshow startup [in D:\rfid\rfid-signin-python\app\__init__.py:36]
2018-12-19 14:51:01,703 ERROR: Exception on /group/TEST [GET] [in d:\rfid\venv\lib\site-packages\flask\app.py:1761]
Traceback (most recent call last):
  File "d:\rfid\venv\lib\site-packages\flask\app.py", line 2292, in wsgi_app
    response = self.full_dispatch_request()
  File "d:\rfid\venv\lib\site-packages\flask\app.py", line 1815, in full_dispatch_request
    rv = self.handle_user_exception(e)
  File "d:\rfid\venv\lib\site-packages\flask_cors\extension.py", line 161, in wrapped_function
    return cors_after_request(app.make_response(f(*args, **kwargs)))
  File "d:\rfid\venv\lib\site-packages\flask\app.py", line 1718, in handle_user_exception
    reraise(exc_type, exc_value, tb)
  File "d:\rfid\venv\lib\site-packages\flask\_compat.py", line 35, in reraise
    raise value
  File "d:\rfid\venv\lib\site-packages\flask\app.py", line 1813, in full_dispatch_request
    rv = self.dispatch_request()
  File "d:\rfid\venv\lib\site-packages\flask\app.py", line 1799, in dispatch_request
    return self.view_functions[rule.endpoint](**req.view_args)
  File "D:\rfid\rfid-signin-python\app\routes.py", line 240, in group
    result = kcluster(parent)
  File "D:\rfid\rfid-signin-python\app\algorithms\kmean.py", line 24, in kcluster
    for i in range(len(rows[0]))]
  File "D:\rfid\rfid-signin-python\app\algorithms\kmean.py", line 24, in <listcomp>
    for i in range(len(rows[0]))]
  File "D:\rfid\rfid-signin-python\app\algorithms\kmean.py", line 23, in <listcomp>
    ranges = [(min([row[i] for row in rows]), max([row[i] for row in rows]))
IndexError: list index out of range
2018-12-19 14:54:47,024 ERROR: Exception on /group/TEST [GET] [in d:\rfid\venv\lib\site-packages\flask\app.py:1761]
Traceback (most recent call last):
  File "d:\rfid\venv\lib\site-packages\flask\app.py", line 2292, in wsgi_app
    response = self.full_dispatch_request()
  File "d:\rfid\venv\lib\site-packages\flask\app.py", line 1815, in full_dispatch_request
    rv = self.handle_user_exception(e)
  File "d:\rfid\venv\lib\site-packages\flask_cors\extension.py", line 161, in wrapped_function
    return cors_after_request(app.make_response(f(*args, **kwargs)))
  File "d:\rfid\venv\lib\site-packages\flask\app.py", line 1718, in handle_user_exception
    reraise(exc_type, exc_value, tb)
  File "d:\rfid\venv\lib\site-packages\flask\_compat.py", line 35, in reraise
    raise value
  File "d:\rfid\venv\lib\site-packages\flask\app.py", line 1813, in full_dispatch_request
    rv = self.dispatch_request()
  File "d:\rfid\venv\lib\site-packages\flask\app.py", line 1799, in dispatch_request
    return self.view_functions[rule.endpoint](**req.view_args)
  File "D:\rfid\rfid-signin-python\app\routes.py", line 240, in group
    result = kcluster(parent)
  File "D:\rfid\rfid-signin-python\app\algorithms\kmean.py", line 24, in kcluster
    if len(rows[i]) != maxlen:
  File "D:\rfid\rfid-signin-python\app\algorithms\kmean.py", line 24, in <listcomp>
    if len(rows[i]) != maxlen:
  File "D:\rfid\rfid-signin-python\app\algorithms\kmean.py", line 23, in <listcomp>
    for i in range(len(rows)):
IndexError: list index out of range
2018-12-19 14:55:13,532 INFO: Serialshow startup [in D:\rfid\rfid-signin-python\app\__init__.py:36]
2018-12-19 14:55:15,194 ERROR: Exception on /group/TEST [GET] [in d:\rfid\venv\lib\site-packages\flask\app.py:1761]
Traceback (most recent call last):
  File "d:\rfid\venv\lib\site-packages\flask\app.py", line 2292, in wsgi_app
    response = self.full_dispatch_request()
  File "d:\rfid\venv\lib\site-packages\flask\app.py", line 1815, in full_dispatch_request
    rv = self.handle_user_exception(e)
  File "d:\rfid\venv\lib\site-packages\flask_cors\extension.py", line 161, in wrapped_function
    return cors_after_request(app.make_response(f(*args, **kwargs)))
  File "d:\rfid\venv\lib\site-packages\flask\app.py", line 1718, in handle_user_exception
    reraise(exc_type, exc_value, tb)
  File "d:\rfid\venv\lib\site-packages\flask\_compat.py", line 35, in reraise
    raise value
  File "d:\rfid\venv\lib\site-packages\flask\app.py", line 1813, in full_dispatch_request
    rv = self.dispatch_request()
  File "d:\rfid\venv\lib\site-packages\flask\app.py", line 1799, in dispatch_request
    return self.view_functions[rule.endpoint](**req.view_args)
  File "D:\rfid\rfid-signin-python\app\routes.py", line 240, in group
    result = kcluster(parent)
  File "D:\rfid\rfid-signin-python\app\algorithms\kmean.py", line 29, in kcluster
    for i in range(len(rows[0]))]
  File "D:\rfid\rfid-signin-python\app\algorithms\kmean.py", line 29, in <listcomp>
    for i in range(len(rows[0]))]
  File "D:\rfid\rfid-signin-python\app\algorithms\kmean.py", line 28, in <listcomp>
    ranges = [(min([row[i] for row in rows]), max([row[i] for row in rows]))
IndexError: list index out of range
2018-12-19 14:55:42,115 INFO: Serialshow startup [in D:\rfid\rfid-signin-python\app\__init__.py:36]
2018-12-19 14:55:43,735 ERROR: Exception on /group/TEST [GET] [in d:\rfid\venv\lib\site-packages\flask\app.py:1761]
Traceback (most recent call last):
  File "d:\rfid\venv\lib\site-packages\flask\app.py", line 2292, in wsgi_app
    response = self.full_dispatch_request()
  File "d:\rfid\venv\lib\site-packages\flask\app.py", line 1815, in full_dispatch_request
    rv = self.handle_user_exception(e)
  File "d:\rfid\venv\lib\site-packages\flask_cors\extension.py", line 161, in wrapped_function
    return cors_after_request(app.make_response(f(*args, **kwargs)))
  File "d:\rfid\venv\lib\site-packages\flask\app.py", line 1718, in handle_user_exception
    reraise(exc_type, exc_value, tb)
  File "d:\rfid\venv\lib\site-packages\flask\_compat.py", line 35, in reraise
    raise value
  File "d:\rfid\venv\lib\site-packages\flask\app.py", line 1813, in full_dispatch_request
    rv = self.dispatch_request()
  File "d:\rfid\venv\lib\site-packages\flask\app.py", line 1799, in dispatch_request
    return self.view_functions[rule.endpoint](**req.view_args)
  File "D:\rfid\rfid-signin-python\app\routes.py", line 240, in group
    result = kcluster(parent)
  File "D:\rfid\rfid-signin-python\app\algorithms\kmean.py", line 30, in kcluster
    for i in range(len(rows[0]))]
  File "D:\rfid\rfid-signin-python\app\algorithms\kmean.py", line 30, in <listcomp>
    for i in range(len(rows[0]))]
  File "D:\rfid\rfid-signin-python\app\algorithms\kmean.py", line 29, in <listcomp>
    ranges = [(min([row[i] for row in rows]), max([row[i] for row in rows]))
IndexError: list index out of range
