2018-10-21 12:08:42,427 ERROR: Exception on / [GET] [in c:\users\q\appdata\local\programs\python\python36-32\lib\site-packages\flask\app.py:1761]
Traceback (most recent call last):
  File "c:\users\q\appdata\local\programs\python\python36-32\lib\site-packages\flask\app.py", line 2292, in wsgi_app
    response = self.full_dispatch_request()
  File "c:\users\q\appdata\local\programs\python\python36-32\lib\site-packages\flask\app.py", line 1815, in full_dispatch_request
    rv = self.handle_user_exception(e)
  File "c:\users\q\appdata\local\programs\python\python36-32\lib\site-packages\flask\app.py", line 1718, in handle_user_exception
    reraise(exc_type, exc_value, tb)
  File "c:\users\q\appdata\local\programs\python\python36-32\lib\site-packages\flask\_compat.py", line 35, in reraise
    raise value
  File "c:\users\q\appdata\local\programs\python\python36-32\lib\site-packages\flask\app.py", line 1813, in full_dispatch_request
    rv = self.dispatch_request()
  File "c:\users\q\appdata\local\programs\python\python36-32\lib\site-packages\flask\app.py", line 1799, in dispatch_request
    return self.view_functions[rule.endpoint](**req.view_args)
  File "D:\serialshow\app\routes.py", line 22, in index
    curr_class = current_user.class_name
  File "c:\users\q\appdata\local\programs\python\python36-32\lib\site-packages\werkzeug\local.py", line 347, in __getattr__
    return getattr(self._get_current_object(), name)
AttributeError: 'AnonymousUserMixin' object has no attribute 'class_name'
2018-10-21 13:16:02,897 INFO: Serialshow startup [in D:\serialshow\app\__init__.py:28]
2018-10-21 13:16:11,141 ERROR: Exception on / [GET] [in c:\users\q\appdata\local\programs\python\python36-32\lib\site-packages\flask\app.py:1761]
Traceback (most recent call last):
  File "c:\users\q\appdata\local\programs\python\python36-32\lib\site-packages\flask\app.py", line 2292, in wsgi_app
    response = self.full_dispatch_request()
  File "c:\users\q\appdata\local\programs\python\python36-32\lib\site-packages\flask\app.py", line 1815, in full_dispatch_request
    rv = self.handle_user_exception(e)
  File "c:\users\q\appdata\local\programs\python\python36-32\lib\site-packages\flask\app.py", line 1718, in handle_user_exception
    reraise(exc_type, exc_value, tb)
  File "c:\users\q\appdata\local\programs\python\python36-32\lib\site-packages\flask\_compat.py", line 35, in reraise
    raise value
  File "c:\users\q\appdata\local\programs\python\python36-32\lib\site-packages\flask\app.py", line 1811, in full_dispatch_request
    rv = self.preprocess_request()
  File "c:\users\q\appdata\local\programs\python\python36-32\lib\site-packages\flask\app.py", line 2087, in preprocess_request
    rv = func()
  File "D:\serialshow\app\routes.py", line 16, in before_request
    users.append(current_user.class_token)
NameError: name 'users' is not defined
2018-10-21 13:16:11,184 ERROR: Exception on /static/css/404.css [GET] [in c:\users\q\appdata\local\programs\python\python36-32\lib\site-packages\flask\app.py:1761]
Traceback (most recent call last):
  File "c:\users\q\appdata\local\programs\python\python36-32\lib\site-packages\flask\app.py", line 2292, in wsgi_app
    response = self.full_dispatch_request()
  File "c:\users\q\appdata\local\programs\python\python36-32\lib\site-packages\flask\app.py", line 1815, in full_dispatch_request
    rv = self.handle_user_exception(e)
  File "c:\users\q\appdata\local\programs\python\python36-32\lib\site-packages\flask\app.py", line 1718, in handle_user_exception
    reraise(exc_type, exc_value, tb)
  File "c:\users\q\appdata\local\programs\python\python36-32\lib\site-packages\flask\_compat.py", line 35, in reraise
    raise value
  File "c:\users\q\appdata\local\programs\python\python36-32\lib\site-packages\flask\app.py", line 1811, in full_dispatch_request
    rv = self.preprocess_request()
  File "c:\users\q\appdata\local\programs\python\python36-32\lib\site-packages\flask\app.py", line 2087, in preprocess_request
    rv = func()
  File "D:\serialshow\app\routes.py", line 16, in before_request
    users.append(current_user.class_token)
NameError: name 'users' is not defined
2018-10-21 13:16:11,201 ERROR: Exception on /static/css/404.css [GET] [in c:\users\q\appdata\local\programs\python\python36-32\lib\site-packages\flask\app.py:1761]
Traceback (most recent call last):
  File "c:\users\q\appdata\local\programs\python\python36-32\lib\site-packages\flask\app.py", line 2292, in wsgi_app
    response = self.full_dispatch_request()
  File "c:\users\q\appdata\local\programs\python\python36-32\lib\site-packages\flask\app.py", line 1815, in full_dispatch_request
    rv = self.handle_user_exception(e)
  File "c:\users\q\appdata\local\programs\python\python36-32\lib\site-packages\flask\app.py", line 1718, in handle_user_exception
    reraise(exc_type, exc_value, tb)
  File "c:\users\q\appdata\local\programs\python\python36-32\lib\site-packages\flask\_compat.py", line 35, in reraise
    raise value
  File "c:\users\q\appdata\local\programs\python\python36-32\lib\site-packages\flask\app.py", line 1811, in full_dispatch_request
    rv = self.preprocess_request()
  File "c:\users\q\appdata\local\programs\python\python36-32\lib\site-packages\flask\app.py", line 2087, in preprocess_request
    rv = func()
  File "D:\serialshow\app\routes.py", line 16, in before_request
    users.append(current_user.class_token)
NameError: name 'users' is not defined
2018-10-21 13:16:11,329 ERROR: Exception on /favicon.ico [GET] [in c:\users\q\appdata\local\programs\python\python36-32\lib\site-packages\flask\app.py:1761]
Traceback (most recent call last):
  File "c:\users\q\appdata\local\programs\python\python36-32\lib\site-packages\flask\app.py", line 2292, in wsgi_app
    response = self.full_dispatch_request()
  File "c:\users\q\appdata\local\programs\python\python36-32\lib\site-packages\flask\app.py", line 1815, in full_dispatch_request
    rv = self.handle_user_exception(e)
  File "c:\users\q\appdata\local\programs\python\python36-32\lib\site-packages\flask\app.py", line 1718, in handle_user_exception
    reraise(exc_type, exc_value, tb)
  File "c:\users\q\appdata\local\programs\python\python36-32\lib\site-packages\flask\_compat.py", line 35, in reraise
    raise value
  File "c:\users\q\appdata\local\programs\python\python36-32\lib\site-packages\flask\app.py", line 1811, in full_dispatch_request
    rv = self.preprocess_request()
  File "c:\users\q\appdata\local\programs\python\python36-32\lib\site-packages\flask\app.py", line 2087, in preprocess_request
    rv = func()
  File "D:\serialshow\app\routes.py", line 16, in before_request
    users.append(current_user.class_token)
NameError: name 'users' is not defined
2018-10-21 13:16:29,868 INFO: Serialshow startup [in D:\serialshow\app\__init__.py:28]
2018-10-21 13:16:31,859 ERROR: Exception on / [GET] [in c:\users\q\appdata\local\programs\python\python36-32\lib\site-packages\flask\app.py:1761]
Traceback (most recent call last):
  File "c:\users\q\appdata\local\programs\python\python36-32\lib\site-packages\flask\app.py", line 2292, in wsgi_app
    response = self.full_dispatch_request()
  File "c:\users\q\appdata\local\programs\python\python36-32\lib\site-packages\flask\app.py", line 1815, in full_dispatch_request
    rv = self.handle_user_exception(e)
  File "c:\users\q\appdata\local\programs\python\python36-32\lib\site-packages\flask\app.py", line 1718, in handle_user_exception
    reraise(exc_type, exc_value, tb)
  File "c:\users\q\appdata\local\programs\python\python36-32\lib\site-packages\flask\_compat.py", line 35, in reraise
    raise value
  File "c:\users\q\appdata\local\programs\python\python36-32\lib\site-packages\flask\app.py", line 1813, in full_dispatch_request
    rv = self.dispatch_request()
  File "c:\users\q\appdata\local\programs\python\python36-32\lib\site-packages\flask\app.py", line 1799, in dispatch_request
    return self.view_functions[rule.endpoint](**req.view_args)
  File "D:\serialshow\app\routes.py", line 24, in index
    r.set('curr_token', curr_class.class_token)
AttributeError: 'str' object has no attribute 'class_token'
2018-10-21 13:19:40,464 INFO: Serialshow startup [in D:\serialshow\app\__init__.py:28]
2018-10-21 13:19:43,396 ERROR: Exception on / [GET] [in c:\users\q\appdata\local\programs\python\python36-32\lib\site-packages\flask\app.py:1761]
Traceback (most recent call last):
  File "c:\users\q\appdata\local\programs\python\python36-32\lib\site-packages\flask\app.py", line 2292, in wsgi_app
    response = self.full_dispatch_request()
  File "c:\users\q\appdata\local\programs\python\python36-32\lib\site-packages\flask\app.py", line 1815, in full_dispatch_request
    rv = self.handle_user_exception(e)
  File "c:\users\q\appdata\local\programs\python\python36-32\lib\site-packages\flask\app.py", line 1718, in handle_user_exception
    reraise(exc_type, exc_value, tb)
  File "c:\users\q\appdata\local\programs\python\python36-32\lib\site-packages\flask\_compat.py", line 35, in reraise
    raise value
  File "c:\users\q\appdata\local\programs\python\python36-32\lib\site-packages\flask\app.py", line 1813, in full_dispatch_request
    rv = self.dispatch_request()
  File "c:\users\q\appdata\local\programs\python\python36-32\lib\site-packages\flask\app.py", line 1799, in dispatch_request
    return self.view_functions[rule.endpoint](**req.view_args)
  File "D:\serialshow\app\routes.py", line 23, in index
    r.set('curr_token', curr_user.class_token)
NameError: name 'curr_user' is not defined
2018-10-21 13:20:09,305 INFO: Serialshow startup [in D:\serialshow\app\__init__.py:28]
